Workbook

Sheet HOTEL
A1: Id_Tempat | B1: Nama_Tempat | C1: Estimasi_Harga | D1: Latitude | E1: Longitude
A2: 1 | B2: SUPER OYO Flagship 90502 Holistay Malang New | C2: 347052 | D2: -7.9368115 | E2: 112.64869
A3: 2 | B3: Hotel OYO 709 Menjangan Residen | C3: 51823 | D3: -8.0040178 | E3: 112.61394 | I3: Kiri (0 pada Long) | J3: Tengah (0.5 pada Long) | K3: Kanan (1 pada Long)
A4: 3 | B4: Super OYO 1376 Kina Family Residence Syariah | C4: 158466 | D4: -7.943296 | E4: 112.60138 | H4: Atas (1 pada Lat) | I4: Pojok Kiri Atas | J4: Utara Tengah | K4: Pojok Kanan Atas
A5: 4 | B5: OYO Flagship 90723 Khalifi House Malang | C5: 220540 | D5: -7.9694153 | E5: 112.66841
A6: 5 | B6: OYO 94769 Griya Djati Syariah 2 | C6: 123967 | D6: -7.9859953 | E6: 112.65978 | I6: (Area Batu Utara/Cangar) | J6: (Lawang/Singosari) | K6: (Arah Bromo)
A7: 6 | B7: SPOT ON 2689 Safira Family Residence | C7: 119934 | D7: -7.8721185 | E7: 112.67909 | H7: Tengah (0.5 pada Lat) | I7: Barat Tengah | J7: PUSAT KOTA | K7: Timur Tengah
A8: 7 | B8: OYO 90684 Happy Homestay Syariah | C8: 214198 | D8: -7.9351406 | E8: 112.70059
A9: 8 | B9: OYO LIfe 1036 Hotel Palem 1 Syariah | C9: 353157 | D9: -7.9689919 | E9: 112.63127 | I9: (Kota Batu) | J9: (Alun-alun Malang) | K9: (Tumpang)
A10: 9 | B10: SPOT ON 90797 Sukun Syariah Homestay | C10: 154217 | D10: -8.0091813 | E10: 112.62038 | H10: Bawah (0 pada Lat) | I10: Pojok Kiri Bawah | J10: Selatan Tengah | K10: Pojok Kanan Bawah
A11: 10 | B11: OYO 90383 Avisha Guest House Syariah | C11: 259001 | D11: -7.9670985 | E11: 112.64287
A12: 11 | B12: OYO 353 Loesje Guest House Syariah | C12: 300000 | D12: -7.9769477 | E12: 112.62528 | I12: (Perbatasan Blitar) | J12: (Kepanjen) | K12: (Lumajang)
A13: 12 | B13: BTC Syariah near RS Saiful Anwar | C13: 36239 | D13: -7.9644232 | E13: 112.63107
A14: 13 | B14: OYO 778 Guest House Amalia Malang | C14: 281083 | D14: -7.967616 | E14: 112.62621
A15: 14 | B15: OYO 3350 Cozy Residence | C15: 365618 | D15: -7.9454091 | E15: 112.6349
A16: 15 | B16: Serayu Homestay Syariah | C16: 45892 | D16: -7.9548405 | E16: 112.61123
A17: 16 | B17: OYO 90319 Angler Guest House Malang | C17: 36239 | D17: -7.9642849 | E17: 112.62215
A18: 17 | B18: OYO Life 92568 Penginapan Joglo Syariah | C18: 103035 | D18: -8.1186834 | E18: 112.56701
A19: 18 | B19: OYO 90303 Cafe & Homestay Kolam Pancing Abah | C19: 142451 | D19: -7.9133065 | E19: 112.63644
A20: 19 | B20: D Maktab Syariah Mitra RedDoorz Malang | C20: 233100 | D20: -7.9510225 | E20: 112.62663
A21: 20 | B21: OYO 94148 Forzando Hotel | C21: 90344 | D21: -7.9223935 | E21: 112.60841
A22: 21 | B22: Forzando House Redpartner near Universitas Muhammadiyah Malang | C22: 90344 | D22: -7.9219222 | E22: 112.6085
A23: 22 | B23: OYO 2771 D'soetta | C23: 237920 | D23: -7.9392536 | E23: 112.62524
A24: 23 | B24: OYO 1468 SM House | C24: 269126 | D24: -7.9322681 | E24: 112.62941
... A364: 363 | B364: My Dormy Hostel UMM | C364: 507806 | D364: -7.9233879 | E364: 112.60159
A366: NORMALISASI
A369: Id_Tempat | B369: Nama_Tempat | C369: Estimasi_Harga | D369: Latitude | E369: Longitude
A370: 1 | B370: SUPER OYO Flagship 90502 Holistay Malang New | C370: =(C2-MIN($C$2:$C$364)) / (MAX($C$2:$C$364)-MIN($C$2:$C$364)) | D370: =(D2-MIN($D$2:$D$364)) / (MAX($D$2:$D$364)-MIN($D$2:$D$364)) | E370: =(E2-MIN($E$2:$E$364)) / (MAX($E$2:$E$364)-MIN($E$2:$E$364))
A371: 2 | B371: Hotel OYO 709 Menjangan Residen | C371: =(C3-MIN($C$2:$C$364)) / (MAX($C$2:$C$364)-MIN($C$2:$C$364)) | D371: =(D3-MIN($D$2:$D$364)) / (MAX($D$2:$D$364)-MIN($D$2:$D$364)) | E371: =(E3-MIN($E$2:$E$364)) / (MAX($E$2:$E$364)-MIN($E$2:$E$364))
A372: 3 | B372: Super OYO 1376 Kina Family Residence Syariah | C372: =(C4-MIN($C$2:$C$364)) / (MAX($C$2:$C$364)-MIN($C$2:$C$364)) | D372: =(D4-MIN($D$2:$D$364)) / (MAX($D$2:$D$364)-MIN($D$2:$D$364)) | E372: =(E4-MIN($E$2:$E$364)) / (MAX($E$2:$E$364)-MIN($E$2:$E$364))
A373: 4 | B373: OYO Flagship 90723 Khalifi House Malang | C373: =(C5-MIN($C$2:$C$364)) / (MAX($C$2:$C$364)-MIN($C$2:$C$364)) | D373: =(D5-MIN($D$2:$D$364)) / (MAX($D$2:$D$364)-MIN($D$2:$D$364)) | E373: =(E5-MIN($E$2:$E$364)) / (MAX($E$2:$E$364)-MIN($E$2:$E$364))
A374: 5 | B374: OYO 94769 Griya Djati Syariah 2 | C374: =(C6-MIN($C$2:$C$364)) / (MAX($C$2:$C$364)-MIN($C$2:$C$364)) | D374: =(D6-MIN($D$2:$D$364)) / (MAX($D$2:$D$364)-MIN($D$2:$D$364)) | E374: =(E6-MIN($E$2:$E$364)) / (MAX($E$2:$E$364)-MIN($E$2:$E$364))
A375: 6 | B375: SPOT ON 2689 Safira Family Residence | C375: =(C7-MIN($C$2:$C$364)) / (MAX($C$2:$C$364)-MIN($C$2:$C$364)) | D375: =(D7-MIN($D$2:$D$364)) / (MAX($D$2:$D$364)-MIN($D$2:$D$364)) | E375: =(E7-MIN($E$2:$E$364)) / (MAX($E$2:$E$364)-MIN($E$2:$E$364))
A376: 7 | B376: OYO 90684 Happy Homestay Syariah | C376: =(C8-MIN($C$2:$C$364)) / (MAX($C$2:$C$364)-MIN($C$2:$C$364)) | D376: =(D8-MIN($D$2:$D$364)) / (MAX($D$2:$D$364)-MIN($D$2:$D$364)) | E376: =(E8-MIN($E$2:$E$364)) / (MAX($E$2:$E$364)-MIN($E$2:$E$364))
A377: 8 | B377: OYO LIfe 1036 Hotel Palem 1 Syariah | C377: =(C9-MIN($C$2:$C$364)) / (MAX($C$2:$C$364)-MIN($C$2:$C$364)) | D377: =(D9-MIN($D$2:$D$364)) / (MAX($D$2:$D$364)-MIN($D$2:$D$364)) | E377: =(E9-MIN($E$2:$E$364)) / (MAX($E$2:$E$364)-MIN($E$2:$E$364))
A378: 9 | B378: SPOT ON 90797 Sukun Syariah Homestay | C378: =(C10-MIN($C$2:$C$364)) / (MAX($C$2:$C$364)-MIN($C$2:$C$364)) | D378: =(D10-MIN($D$2:$D$364)) / (MAX($D$2:$D$364)-MIN($D$2:$D$364)) | E378: =(E10-MIN($E$2:$E$364)) / (MAX($E$2:$E$364)-MIN($E$2:$E$364))
A379: 10 | B379: OYO 90383 Avisha Guest House Syariah | C379: =(C11-MIN($C$2:$C$364)) / (MAX($C$2:$C$364)-MIN($C$2:$C$364)) | D379: =(D11-MIN($D$2:$D$364)) / (MAX($D$2:$D$364)-MIN($D$2:$D$364)) | E379: =(E11-MIN($E$2:$E$364)) / (MAX($E$2:$E$364)-MIN($E$2:$E$364))
A380: 11 | B380: OYO 353 Loesje Guest House Syariah | C380: =(C12-MIN($C$2:$C$364)) / (MAX($C$2:$C$364)-MIN($C$2:$C$364)) | D380: =(D12-MIN($D$2:$D$364)) / (MAX($D$2:$D$364)-MIN($D$2:$D$364)) | E380: =(E12-MIN($E$2:$E$364)) / (MAX($E$2:$E$364)-MIN($E$2:$E$364))
A381: 12 | B381: BTC Syariah near RS Saiful Anwar | C381: =(C13-MIN($C$2:$C$364)) / (MAX($C$2:$C$364)-MIN($C$2:$C$364)) | D381: =(D13-MIN($D$2:$D$364)) / (MAX($D$2:$D$364)-MIN($D$2:$D$364)) | E381: =(E13-MIN($E$2:$E$364)) / (MAX($E$2:$E$364)-MIN($E$2:$E$364))
... A732: 363 | B732: My Dormy Hostel UMM | C732: =(C364-MIN($C$2:$C$364)) / (MAX($C$2:$C$364)-MIN($C$2:$C$364)) | D732: =(D364-MIN($D$2:$D$364)) / (MAX($D$2:$D$364)-MIN($D$2:$D$364)) | E732: =(E364-MIN($E$2:$E$364)) / (MAX($E$2:$E$364)-MIN($E$2:$E$364))

Sheet WISATA
A1: Id_Tempat | B1: Nama_Tempat | C1: Harga_Tiket | D1: Latitude | E1: Longitude
A2: 1 | B2: Masjid Tiban Malang (pp.Salafiah Bihaaru Bahri) | C2: 2000 | D2: -8.1508285 | E2: 112.71311 | I2: Kiri (0 pada Long) | J2: Tengah (0.5 pada Long) | K2: Kanan (1 pada Long)
A3: 2 | B3: Wisata Religi Gunung Mujur ꦒꦸꦤꦸꦁꦩꦸꦗꦸꦂ | C3: 10000 | D3: -7.8263032 | E3: 112.59311 | H3: Atas (1 pada Lat) | I3: Pojok Kiri Atas | J3: Utara Tengah | K3: Pojok Kanan Atas
A4: 3 | B4: Masjid Agung Jami' Kota Malang | C4: 0 | D4: -7.9823828 | E4: 112.62972
A5: 4 | B5: Makam Mbah Batu | C5: 3000 | D5: -7.8563341 | E5: 112.53524 | I5: (Area Batu Utara/Cangar) | J5: (Lawang/Singosari) | K5: (Arah Bromo)
A6: 5 | B6: KWJ MALANG | C6: 5000 | D6: -7.9831 | E6: 112.63748 | H6: Tengah (0.5 pada Lat) | I6: Barat Tengah | J6: PUSAT KOTA | K6: Timur Tengah
A7: 6 | B7: Pesarean Gunung Kawi | C7: 3000 | D7: -8.0232006 | E7: 112.49327
A8: 7 | B8: Makam Ki Ageng Gribig | C8: 48000 | D8: -7.9809099 | E8: 112.66565 | I8: (Kota Batu) | J8: (Alun-alun Malang) | K8: (Tumpang)
A9: 8 | B9: Pura Luhur Giri Arjuno | C9: 11000 | D9: -7.7852789 | E9: 112.54731 | H9: Bawah (0 pada Lat) | I9: Pojok Kiri Bawah | J9: Selatan Tengah | K9: Pojok Kanan Bawah
A10: 9 | B10: Masjid An-Nur | C10: 10000 | D10: -7.9639168 | E10: 112.62949
A11: 10 | B11: MAKAM MBAH JAGOPATI | C11: 0 | D11: -8.0685875 | E11: 112.65952 | I11: (Perbatasan Blitar) | J11: (Kepanjen) | K11: (Lumajang)
A12: 11 | B12: Wisata Religi Sumber 9 | C12: 5000 | D12: -8.1721911 | E12: 112.54728
A13: 12 | B13: Parkir mobil gratis Masjid tiban turen | C13: 5000 | D13: -8.1514495 | E13: 112.71231
A14: 13 | B14: Punden Mbah Mogok | C14: 10000 | D14: -7.9619438 | E14: 112.60487
A15: 14 | B15: Maqam Al Habib Abdullah Bin Abdul Qadir Bilfaqih | C15: 20000 | D15: -7.9890997 | E15: 112.62386
A16: 15 | B16: Pura Luhur Dwijawarsa | C16: 104500 | D16: -7.9953961 | E16: 112.66104
A17: 16 | B17: TPU Kasin | C17: 30000 | D17: -7.9896057 | E17: 112.62396
A18: 17 | B18: Puncak Gunung Banyak/paralayang | C18: 10000 | D18: -7.8549572 | E18: 112.49638
A19: 18 | B19: Air Terjun Coban Rondo Pujon | C19: 35000 | D19: -7.8846458 | E19: 112.47682
A20: 19 | B20: Agrowisata Teh Wonosari | C20: 15000 | D20: -7.8204902 | E20: 112.64315
A21: 20 | B21: Puncak Budug Asu | C21: 10000 | D21: -7.807287 | E21: 112.62141
A22: 21 | B22: Keraton Gunung Kawi | C22: 5000 | D22: -8.0027708 | E22: 112.486
A23: 22 | B23: Bukit Nirwana | C23: 10000 | D23: -7.8617098 | E23: 112.46002
... A189: 188 | B189: Wisata Air Sumber Jenon | C189: 10000 | D189: -8.0504995 | E189: 112.7163
A192: NORMALISASI
A195: Id_Tempat | B195: Nama_Tempat | C195: Estimasi_Harga | D195: Latitude | E195: Longitude
A196: 1 | B196: Masjid Tiban Malang (pp.Salafiah Bihaaru Bahri) | C196: =(C2-MIN($C$2:$C$189)) / (MAX($C$2:$C$189)-MIN($C$2:$C$189)) | D196: =(D2-MIN($D$2:D$188)) / (MAX($D$2:D$188)-MIN($D$2:D$188)) | E196: =(E2-MIN($E2:E$189)) / (MAX($E$2:E$189)-MIN($E$2:E$189))
A197: 2 | B197: Wisata Religi Gunung Mujur ꦒꦸꦤꦸꦁꦩꦸꦗꦸꦂ | C197: =(C3-MIN($C$2:$C$189)) / (MAX($C$2:$C$189)-MIN($C$2:$C$189)) | D197: =(D3-MIN($D$2:D$188)) / (MAX($D$2:D$188)-MIN($D$2:D$188)) | E197: =(E3-MIN($E3:E$189)) / (MAX($E$2:E$189)-MIN($E$2:E$189))
A198: 3 | B198: Masjid Agung Jami' Kota Malang | C198: =(C4-MIN($C$2:$C$189)) / (MAX($C$2:$C$189)-MIN($C$2:$C$189)) | D198: =(D4-MIN($D$2:D$188)) / (MAX($D$2:D$188)-MIN($D$2:D$188)) | E198: =(E4-MIN($E4:E$189)) / (MAX($E$2:E$189)-MIN($E$2:E$189))
A199: 4 | B199: Makam Mbah Batu | C199: =(C5-MIN($C$2:$C$189)) / (MAX($C$2:$C$189)-MIN($C$2:$C$189)) | D199: =(D5-MIN($D$2:D$188)) / (MAX($D$2:D$188)-MIN($D$2:D$188)) | E199: =(E5-MIN($E5:E$189)) / (MAX($E$2:E$189)-MIN($E$2:E$189))
A200: 5 | B200: KWJ MALANG | C200: =(C6-MIN($C$2:$C$189)) / (MAX($C$2:$C$189)-MIN($C$2:$C$189)) | D200: =(D6-MIN($D$2:D$188)) / (MAX($D$2:D$188)-MIN($D$2:D$188)) | E200: =(E6-MIN($E6:E$189)) / (MAX($E$2:E$189)-MIN($E$2:E$189))
A201: 6 | B201: Pesarean Gunung Kawi | C201: =(C7-MIN($C$2:$C$189)) / (MAX($C$2:$C$189)-MIN($C$2:$C$189)) | D201: =(D7-MIN($D$2:D$188)) / (MAX($D$2:D$188)-MIN($D$2:D$188)) | E201: =(E7-MIN($E7:E$189)) / (MAX($E$2:E$189)-MIN($E$2:E$189))
A202: 7 | B202: Makam Ki Ageng Gribig | C202: =(C8-MIN($C$2:$C$189)) / (MAX($C$2:$C$189)-MIN($C$2:$C$189)) | D202: =(D8-MIN($D$2:D$188)) / (MAX($D$2:D$188)-MIN($D$2:D$188)) | E202: =(E8-MIN($E8:E$189)) / (MAX($E$2:E$189)-MIN($E$2:E$189))
A203: 8 | B203: Pura Luhur Giri Arjuno | C203: =(C9-MIN($C$2:$C$189)) / (MAX($C$2:$C$189)-MIN($C$2:$C$189)) | D203: =(D9-MIN($D$2:D$188)) / (MAX($D$2:D$188)-MIN($D$2:D$188)) | E203: =(E9-MIN($E9:E$189)) / (MAX($E$2:E$189)-MIN($E$2:E$189))
A204: 9 | B204: Masjid An-Nur | C204: =(C10-MIN($C$2:$C$189)) / (MAX($C$2:$C$189)-MIN($C$2:$C$189)) | D204: =(D10-MIN($D$2:D$188)) / (MAX($D$2:D$188)-MIN($D$2:D$188)) | E204: =(E10-MIN($E10:E$189)) / (MAX($E$2:E$189)-MIN($E$2:E$189))
A205: 10 | B205: MAKAM MBAH JAGOPATI | C205: =(C11-MIN($C$2:$C$189)) / (MAX($C$2:$C$189)-MIN($C$2:$C$189)) | D205: =(D11-MIN($D$2:D$188)) / (MAX($D$2:D$188)-MIN($D$2:D$188)) | E205: =(E11-MIN($E11:E$189)) / (MAX($E$2:E$189)-MIN($E$2:E$189))
A206: 11 | B206: Wisata Religi Sumber 9 | C206: =(C12-MIN($C$2:$C$189)) / (MAX($C$2:$C$189)-MIN($C$2:$C$189)) | D206: =(D12-MIN($D$2:D$188)) / (MAX($D$2:D$188)-MIN($D$2:D$188)) | E206: =(E12-MIN($E12:E$189)) / (MAX($E$2:E$189)-MIN($E$2:E$189))
A207: 12 | B207: Parkir mobil gratis Masjid tiban turen | C207: =(C13-MIN($C$2:$C$189)) / (MAX($C$2:$C$189)-MIN($C$2:$C$189)) | D207: =(D13-MIN($D$2:D$188)) / (MAX($D$2:D$188)-MIN($D$2:D$188)) | E207: =(E13-MIN($E13:E$189)) / (MAX($E$2:E$189)-MIN($E$2:E$189))
... A383: 188 | B383: Wisata Air Sumber Jenon | C383: =(C189-MIN($C$2:$C$189)) / (MAX($C$2:$C$189)-MIN($C$2:$C$189)) | D383: =(D189-MIN($D$2:D$188)) / (MAX($D$2:D$188)-MIN($D$2:D$188)) | E383: =(E189-MIN($E189:E$189)) / (MAX($E$2:E$189)-MIN($E$2:E$189))

Sheet MAKAN
A1: Id_Tempat | B1: Nama_Tempat | C1: Estimasi_Harga | D1: Latitude | E1: Longitude
A2: 1 | B2: Depot Cwimie Malang | C2: 17000 | D2: -7.2943746 | E2: 112.77862 | I2: Kiri (0 pada Long) | J2: Tengah (0.5 pada Long) | K2: Kanan (1 pada Long)
A3: 2 | B3: Depot Rawon Malang "MM" | C3: 102000 | D3: -7.2785359 | E3: 112.73198 | H3: Atas (1 pada Lat) | I3: Pojok Kiri Atas | J3: Utara Tengah | K3: Pojok Kanan Atas
A4: 3 | B4: Depot J-One | C4: 85000 | D4: -7.2874756 | E4: 112.79455
A5: 4 | B5: Depot Gang Djangkrik Manyar Kertoarjo Surabaya | C5: 242000 | D5: -7.280685 | E5: 112.77053 | I5: (Area Batu Utara/Cangar) | J5: (Lawang/Singosari) | K5: (Arah Bromo)
A6: 5 | B6: Depot Gang Djangkrik Kawi Atas Malang | C6: 121000 | D6: -7.9753699 | E6: 112.61928 | H6: Tengah (0.5 pada Lat) | I6: Barat Tengah | J6: PUSAT KOTA | K6: Timur Tengah
A7: 6 | B7: Depot Pak Bas | C7: 51000 | D7: -7.2815832 | E7: 112.77208
A8: 7 | B8: Depot Ny Kim | C8: 60000 | D8: -7.2977129 | E8: 112.77458 | I8: (Kota Batu) | J8: (Alun-alun Malang) | K8: (Tumpang)
A9: 8 | B9: Depot Gang Djangkrik | C9: 121000 | D9: -7.9568232 | E9: 112.63846 | H9: Bawah (0 pada Lat) | I9: Pojok Kiri Bawah | J9: Selatan Tengah | K9: Pojok Kanan Bawah
A10: 9 | B10: Depot Tanjung Api Malang | C10: 60606 | D10: -7.9650229 | E10: 112.62613
A11: 10 | B11: Depot Sari Rasa | C11: 70000 | D11: -7.9654019 | E11: 112.63411 | I11: (Perbatasan Blitar) | J11: (Kepanjen) | K11: (Lumajang)
A12: 11 | B12: Depot Kayutangan | C12: 45000 | D12: -7.9763697 | E12: 112.63033
A13: 12 | B13: Depot Malang Kuliner | C13: 73700 | D13: -7.9642673 | E13: 112.64005
A14: 13 | B14: Depot Djempolan | C14: 27000 | D14: -7.987635 | E14: 112.63454
A15: 14 | B15: Depot 200 | C15: 22000 | D15: -7.9372434 | E15: 112.60608
A16: 15 | B16: Gudeg Bu Toegijo | C16: 63000 | D16: -7.2884712 | E16: 112.77704
A17: 16 | B17: Depot Arema | C17: 28000 | D17: -7.980489 | E17: 112.65646
A18: 17 | B18: Depot Cak Win | C18: 20000 | D18: -7.2771498 | E18: 112.76136
A19: 18 | B19: Depot Widari | C19: 73700 | D19: -7.9754065 | E19: 112.61952
A20: 19 | B20: Depot 2 Legenda | C20: 41538 | D20: -7.9399474 | E20: 112.63566
A21: 20 | B21: Depot Asri Bu Saeroen | C21: 25000 | D21: -7.9673974 | E21: 112.63384
A22: 21 | B22: Rumah Makan Gloria l Since 1970 | C22: 166100 | D22: -7.9841646 | E22: 112.63359
A23: 22 | B23: Depot Kawanua 1 Malang | C23: 40000 | D23: -7.980493 | E23: 112.6406
... A492: 491 | B492: Nasi Babat Kampung Malang Surabaya | C492: 35000 | D492: -7.2705997 | E492: 112.73519
A495: NORMALISASI
A498: Id_Tempat | B498: Nama_Tempat | C498: Estimasi_Harga | D498: Latitude | E498: Longitude
A499: 1 | B499: Depot Cwimie Malang | C499: =(C2-MIN($C$2:$C$492)) / (MAX($C$2:$C$492)-MIN($C$2:$C$492)) | D499: =(D2-MIN($D$2:$D$492)) / (MAX($D$2:$D$492)-MIN($D$2:$D$492)) | E499: =(E2-MIN($E$2:$E$492)) / (MAX($E$2:$E$492)-MIN($E$2:$E$492))
A500: 2 | B500: Depot Rawon Malang "MM" | C500: =(C3-MIN($C$2:$C$492)) / (MAX($C$2:$C$492)-MIN($C$2:$C$492)) | D500: =(D3-MIN($D$2:$D$492)) / (MAX($D$2:$D$492)-MIN($D$2:$D$492)) | E500: =(E3-MIN($E$2:$E$492)) / (MAX($E$2:$E$492)-MIN($E$2:$E$492))
A501: 3 | B501: Depot J-One | C501: =(C4-MIN($C$2:$C$492)) / (MAX($C$2:$C$492)-MIN($C$2:$C$492)) | D501: =(D4-MIN($D$2:$D$492)) / (MAX($D$2:$D$492)-MIN($D$2:$D$492)) | E501: =(E4-MIN($E$2:$E$492)) / (MAX($E$2:$E$492)-MIN($E$2:$E$492))
A502: 4 | B502: Depot Gang Djangkrik Manyar Kertoarjo Surabaya | C502: =(C5-MIN($C$2:$C$492)) / (MAX($C$2:$C$492)-MIN($C$2:$C$492)) | D502: =(D5-MIN($D$2:$D$492)) / (MAX($D$2:$D$492)-MIN($D$2:$D$492)) | E502: =(E5-MIN($E$2:$E$492)) / (MAX($E$2:$E$492)-MIN($E$2:$E$492))
A503: 5 | B503: Depot Gang Djangkrik Kawi Atas Malang | C503: =(C6-MIN($C$2:$C$492)) / (MAX($C$2:$C$492)-MIN($C$2:$C$492)) | D503: =(D6-MIN($D$2:$D$492)) / (MAX($D$2:$D$492)-MIN($D$2:$D$492)) | E503: =(E6-MIN($E$2:$E$492)) / (MAX($E$2:$E$492)-MIN($E$2:$E$492))
A504: 6 | B504: Depot Pak Bas | C504: =(C7-MIN($C$2:$C$492)) / (MAX($C$2:$C$492)-MIN($C$2:$C$492)) | D504: =(D7-MIN($D$2:$D$492)) / (MAX($D$2:$D$492)-MIN($D$2:$D$492)) | E504: =(E7-MIN($E$2:$E$492)) / (MAX($E$2:$E$492)-MIN($E$2:$E$492))
A505: 7 | B505: Depot Ny Kim | C505: =(C8-MIN($C$2:$C$492)) / (MAX($C$2:$C$492)-MIN($C$2:$C$492)) | D505: =(D8-MIN($D$2:$D$492)) / (MAX($D$2:$D$492)-MIN($D$2:$D$492)) | E505: =(E8-MIN($E$2:$E$492)) / (MAX($E$2:$E$492)-MIN($E$2:$E$492))
A506: 8 | B506: Depot Gang Djangkrik | C506: =(C9-MIN($C$2:$C$492)) / (MAX($C$2:$C$492)-MIN($C$2:$C$492)) | D506: =(D9-MIN($D$2:$D$492)) / (MAX($D$2:$D$492)-MIN($D$2:$D$492)) | E506: =(E9-MIN($E$2:$E$492)) / (MAX($E$2:$E$492)-MIN($E$2:$E$492))
A507: 9 | B507: Depot Tanjung Api Malang | C507: =(C10-MIN($C$2:$C$492)) / (MAX($C$2:$C$492)-MIN($C$2:$C$492)) | D507: =(D10-MIN($D$2:$D$492)) / (MAX($D$2:$D$492)-MIN($D$2:$D$492)) | E507: =(E10-MIN($E$2:$E$492)) / (MAX($E$2:$E$492)-MIN($E$2:$E$492))
A508: 10 | B508: Depot Sari Rasa | C508: =(C11-MIN($C$2:$C$492)) / (MAX($C$2:$C$492)-MIN($C$2:$C$492)) | D508: =(D11-MIN($D$2:$D$492)) / (MAX($D$2:$D$492)-MIN($D$2:$D$492)) | E508: =(E11-MIN($E$2:$E$492)) / (MAX($E$2:$E$492)-MIN($E$2:$E$492))
A509: 11 | B509: Depot Kayutangan | C509: =(C12-MIN($C$2:$C$492)) / (MAX($C$2:$C$492)-MIN($C$2:$C$492)) | D509: =(D12-MIN($D$2:$D$492)) / (MAX($D$2:$D$492)-MIN($D$2:$D$492)) | E509: =(E12-MIN($E$2:$E$492)) / (MAX($E$2:$E$492)-MIN($E$2:$E$492))
A510: 12 | B510: Depot Malang Kuliner | C510: =(C13-MIN($C$2:$C$492)) / (MAX($C$2:$C$492)-MIN($C$2:$C$492)) | D510: =(D13-MIN($D$2:$D$492)) / (MAX($D$2:$D$492)-MIN($D$2:$D$492)) | E510: =(E13-MIN($E$2:$E$492)) / (MAX($E$2:$E$492)-MIN($E$2:$E$492))
... A989: 491 | B989: Nasi Babat Kampung Malang Surabaya | C989: =(C492-MIN($C$2:$C$492)) / (MAX($C$2:$C$492)-MIN($C$2:$C$492)) | D989: =(D492-MIN($D$2:$D$492)) / (MAX($D$2:$D$492)-MIN($D$2:$D$492)) | E989: =(E492-MIN($E$2:$E$492)) / (MAX($E$2:$E$492)-MIN($E$2:$E$492))

Sheet HOTEL HIT_FCM
A1: Nama_Tempat | B1: Norm_Harga | C1: Norm_Lat | D1: Norm_Long | F1: PUSAT CLUSTER | G1: Cluster 1 (Murah) | H1: Cluster 2 (Sedang) | I1: Cluster 3 (Mahal) | K1: Jarak_ke_C1 | L1: Jarak_ke_C2 | M1: Jarak_ke_C3 | O1: Mu_Murah | P1: Mu_Sedang | Q1: Mu_Mahal | S1: Kategori Akhir
A2: SUPER OYO Flagship 90502 Holistay Malang New | B2: 0.086136199 | C2: 0.61327454 | D2: 0.54856906 | G2: 0.057953 | H2: 0.242811 | I2: 0.787523 | K2: =ABS(B2 - $G$2) | L2: =ABS(B2 - $H$2) | M2: =ABS(B2 - $I$2) | O2: =(1/K2^2) / ((1/K2^2) + (1/L2^2) + (1/M2^2)) | P2: =(1/L2^2) / ((1/K2^2) + (1/L2^2) + (1/M2^2)) | Q2: =(1/M2^2) / ((1/K2^2) + (1/L2^2) + (1/M2^2)) | S2: =IF(MAX(O2:Q2)=O2, "Murah", IF(MAX(O2:Q2)=P2, "Sedang", "Mahal"))
A3: Hotel OYO 709 Menjangan Residen | B3: 0.0043188236 | C3: 0.38665397 | D3: 0.38833066 | K3: =ABS(B3 - $G$2) | L3: =ABS(B3 - $H$2) | M3: =ABS(B3 - $I$2) | O3: =(1/K3^2) / ((1/K3^2) + (1/L3^2) + (1/M3^2)) | P3: =(1/L3^2) / ((1/K3^2) + (1/L3^2) + (1/M3^2)) | Q3: =(1/M3^2) / ((1/K3^2) + (1/L3^2) + (1/M3^2)) | S3: =IF(MAX(O3:Q3)=O3, "Murah", IF(MAX(O3:Q3)=P3, "Sedang", "Mahal"))
A4: Super OYO 1376 Kina Family Residence Syariah | B4: 0.033873002 | C4: 0.59140872 | D4: 0.33037918 | G4: =SUMPRODUCT(O2:O364^2, $B$2:$B$364) / SUMSQ(O2:O364) | H4: =SUMPRODUCT(P2:P364^2, $B$2:$B$364) / SUMSQ(P2:P364) | I4: =SUMPRODUCT(Q2:Q364^2, $B$2:$B$364) / SUMSQ(Q2:Q364) | K4: =ABS(B4 - $G$2) | L4: =ABS(B4 - $H$2) | M4: =ABS(B4 - $I$2) | O4: =(1/K4^2) / ((1/K4^2) + (1/L4^2) + (1/M4^2)) | P4: =(1/L4^2) / ((1/K4^2) + (1/L4^2) + (1/M4^2)) | Q4: =(1/M4^2) / ((1/K4^2) + (1/L4^2) + (1/M4^2)) | S4: =IF(MAX(O4:Q4)=O4, "Murah", IF(MAX(O4:Q4)=P4, "Sedang", "Mahal"))
A5: OYO Flagship 90723 Khalifi House Malang | B5: 0.051075687 | C5: 0.50333408 | D5: 0.63952217 | K5: =ABS(B5 - $G$2) | L5: =ABS(B5 - $H$2) | M5: =ABS(B5 - $I$2) | O5: =(1/K5^2) / ((1/K5^2) + (1/L5^2) + (1/M5^2)) | P5: =(1/L5^2) / ((1/K5^2) + (1/L5^2) + (1/M5^2)) | Q5: =(1/M5^2) / ((1/K5^2) + (1/L5^2) + (1/M5^2)) | S5: =IF(MAX(O5:Q5)=O5, "Murah", IF(MAX(O5:Q5)=P5, "Sedang", "Mahal"))
A6: OYO 94769 Griya Djati Syariah 2 | B6: 0.024312228 | C6: 0.44742609 | D6: 0.59972266 | K6: =ABS(B6 - $G$2) | L6: =ABS(B6 - $H$2) | M6: =ABS(B6 - $I$2) | O6: =(1/K6^2) / ((1/K6^2) + (1/L6^2) + (1/M6^2)) | P6: =(1/L6^2) / ((1/K6^2) + (1/L6^2) + (1/M6^2)) | Q6: =(1/M6^2) / ((1/K6^2) + (1/L6^2) + (1/M6^2)) | S6: =IF(MAX(O6:Q6)=O6, "Murah", IF(MAX(O6:Q6)=P6, "Sedang", "Mahal"))
A7: SPOT ON 2689 Safira Family Residence | B7: 0.023194555 | C7: 0.83142022 | D7: 0.68877443 | K7: =ABS(B7 - $G$2) | L7: =ABS(B7 - $H$2) | M7: =ABS(B7 - $I$2) | O7: =(1/K7^2) / ((1/K7^2) + (1/L7^2) + (1/M7^2)) | P7: =(1/L7^2) / ((1/K7^2) + (1/L7^2) + (1/M7^2)) | Q7: =(1/M7^2) / ((1/K7^2) + (1/L7^2) + (1/M7^2)) | S7: =IF(MAX(O7:Q7)=O7, "Murah", IF(MAX(O7:Q7)=P7, "Sedang", "Mahal"))
A8: OYO 90684 Happy Homestay Syariah | B8: 0.049318117 | C8: 0.61890884 | D8: 0.78789183 | K8: =ABS(B8 - $G$2) | L8: =ABS(B8 - $H$2) | M8: =ABS(B8 - $I$2) | O8: =(1/K8^2) / ((1/K8^2) + (1/L8^2) + (1/M8^2)) | P8: =(1/L8^2) / ((1/K8^2) + (1/L8^2) + (1/M8^2)) | Q8: =(1/M8^2) / ((1/K8^2) + (1/L8^2) + (1/M8^2)) | S8: =IF(MAX(O8:Q8)=O8, "Murah", IF(MAX(O8:Q8)=P8, "Sedang", "Mahal"))
A9: OYO LIfe 1036 Hotel Palem 1 Syariah | B9: 0.08782809 | C9: 0.50476179 | D9: 0.46824557 | K9: =ABS(B9 - $G$2) | L9: =ABS(B9 - $H$2) | M9: =ABS(B9 - $I$2) | O9: =(1/K9^2) / ((1/K9^2) + (1/L9^2) + (1/M9^2)) | P9: =(1/L9^2) / ((1/K9^2) + (1/L9^2) + (1/M9^2)) | Q9: =(1/M9^2) / ((1/K9^2) + (1/L9^2) + (1/M9^2)) | S9: =IF(MAX(O9:Q9)=O9, "Murah", IF(MAX(O9:Q9)=P9, "Sedang", "Mahal"))
A10: SPOT ON 90797 Sukun Syariah Homestay | B10: 0.032695468 | C10: 0.36924258 | D10: 0.41800183 | K10: =ABS(B10 - $G$2) | L10: =ABS(B10 - $H$2) | M10: =ABS(B10 - $I$2) | O10: =(1/K10^2) / ((1/K10^2) + (1/L10^2) + (1/M10^2)) | P10: =(1/L10^2) / ((1/K10^2) + (1/L10^2) + (1/M10^2)) | Q10: =(1/M10^2) / ((1/K10^2) + (1/L10^2) + (1/M10^2)) | S10: =IF(MAX(O10:Q10)=O10, "Murah", IF(MAX(O10:Q10)=P10, "Sedang", "Mahal"))
A11: OYO 90383 Avisha Guest House Syariah | B11: 0.061734458 | C11: 0.51114636 | D11: 0.5217423 | K11: =ABS(B11 - $G$2) | L11: =ABS(B11 - $H$2) | M11: =ABS(B11 - $I$2) | O11: =(1/K11^2) / ((1/K11^2) + (1/L11^2) + (1/M11^2)) | P11: =(1/L11^2) / ((1/K11^2) + (1/L11^2) + (1/M11^2)) | Q11: =(1/M11^2) / ((1/K11^2) + (1/L11^2) + (1/M11^2)) | S11: =IF(MAX(O11:Q11)=O11, "Murah", IF(MAX(O11:Q11)=P11, "Sedang", "Mahal"))
A12: OYO 353 Loesje Guest House Syariah | B12: 0.073096589 | C12: 0.47793472 | D12: 0.44059565 | K12: =ABS(B12 - $G$2) | L12: =ABS(B12 - $H$2) | M12: =ABS(B12 - $I$2) | O12: =(1/K12^2) / ((1/K12^2) + (1/L12^2) + (1/M12^2)) | P12: =(1/L12^2) / ((1/K12^2) + (1/L12^2) + (1/M12^2)) | Q12: =(1/M12^2) / ((1/K12^2) + (1/L12^2) + (1/M12^2)) | S12: =IF(MAX(O12:Q12)=O12, "Murah", IF(MAX(O12:Q12)=P12, "Sedang", "Mahal"))
A13: BTC Syariah near RS Saiful Anwar | B13: 0 | C13: 0.52016751 | D13: 0.46733248 | K13: =ABS(B13 - $G$2) | L13: =ABS(B13 - $H$2) | M13: =ABS(B13 - $I$2) | O13: =(1/K13^2) / ((1/K13^2) + (1/L13^2) + (1/M13^2)) | P13: =(1/L13^2) / ((1/K13^2) + (1/L13^2) + (1/M13^2)) | Q13: =(1/M13^2) / ((1/K13^2) + (1/L13^2) + (1/M13^2)) | S13: =IF(MAX(O13:Q13)=O13, "Murah", IF(MAX(O13:Q13)=P13, "Sedang", "Mahal"))
A14: OYO 778 Guest House Amalia Malang | B14: 0.067854085 | C14: 0.50940134 | D14: 0.44492266 | K14: =ABS(B14 - $G$2) | L14: =ABS(B14 - $H$2) | M14: =ABS(B14 - $I$2) | O14: =(1/K14^2) / ((1/K14^2) + (1/L14^2) + (1/M14^2)) | P14: =(1/L14^2) / ((1/K14^2) + (1/L14^2) + (1/M14^2)) | Q14: =(1/M14^2) / ((1/K14^2) + (1/L14^2) + (1/M14^2)) | S14: =IF(MAX(O14:Q14)=O14, "Murah", IF(MAX(O14:Q14)=P14, "Sedang", "Mahal"))
A15: OYO 3350 Cozy Residence | B15: 0.09128143 | C15: 0.58428331 | D15: 0.4849569 | K15: =ABS(B15 - $G$2) | L15: =ABS(B15 - $H$2) | M15: =ABS(B15 - $I$2) | O15: =(1/K15^2) / ((1/K15^2) + (1/L15^2) + (1/M15^2)) | P15: =(1/L15^2) / ((1/K15^2) + (1/L15^2) + (1/M15^2)) | Q15: =(1/M15^2) / ((1/K15^2) + (1/L15^2) + (1/M15^2)) | S15: =IF(MAX(O15:Q15)=O15, "Murah", IF(MAX(O15:Q15)=P15, "Sedang", "Mahal"))
A16: Serayu Homestay Syariah | B16: 0.0026751543 | C16: 0.5524805 | D16: 0.37582691 | K16: =ABS(B16 - $G$2) | L16: =ABS(B16 - $H$2) | M16: =ABS(B16 - $I$2) | O16: =(1/K16^2) / ((1/K16^2) + (1/L16^2) + (1/M16^2)) | P16: =(1/L16^2) / ((1/K16^2) + (1/L16^2) + (1/M16^2)) | Q16: =(1/M16^2) / ((1/K16^2) + (1/L16^2) + (1/M16^2)) | S16: =IF(MAX(O16:Q16)=O16, "Murah", IF(MAX(O16:Q16)=P16, "Sedang", "Mahal"))
... A364: My Dormy Hostel UMM | B364: 0.13068626 | C364: 0.6585391 | D364: 0.33135544 | K364: =ABS(B364 - $G$2) | L364: =ABS(B364 - $H$2) | M364: =ABS(B364 - $I$2) | O364: =(1/K364^2) / ((1/K364^2) + (1/L364^2) + (1/M364^2)) | P364: =(1/L364^2) / ((1/K364^2) + (1/L364^2) + (1/M364^2)) | Q364: =(1/M364^2) / ((1/K364^2) + (1/L364^2) + (1/M364^2)) | S364: =IF(MAX(O364:Q364)=O364, "Murah", IF(MAX(O364:Q364)=P364, "Sedang", "Mahal"))

Sheet WISATA HIT_FCM
A1: Nama_Tempat | B1: Estimasi_Harga | C1: Latitude | D1: Longitude | F1: PUSAT CLUSTER | G1: Cluster 1 (Murah) | H1: Cluster 2 (Sedang) | I1: Cluster 3 (Mahal) | K1: Jarak_ke_C1 | L1: Jarak_ke_C2 | M1: Jarak_ke_C3 | O1: Mu_Murah | P1: Mu_Sedang | Q1: Mu_Mahal | S1: Kategori Akhir
A2: Masjid Tiban Malang (pp.Salafiah Bihaaru Bahri) | B2: 0.0034782609 | C2: 0.40578643 | D2: 0.54964041 | G2: 0.025985348 | H2: 0.22791184 | I2: 0.97338755 | K2: =ABS(B2 - $G$2) | L2: =ABS(B2 - $H$2) | M2: =ABS(B2 - $I$2) | O2: =(1/K2^2) / ((1/K2^2) + (1/L2^2) + (1/M2^2)) | P2: =(1/L2^2) / ((1/K2^2) + (1/L2^2) + (1/M2^2)) | Q2: =(1/M2^2) / ((1/K2^2) + (1/L2^2) + (1/M2^2)) | S2: =IF(MAX(O2:Q2)=O2, "Murah", IF(MAX(O2:Q2)=P2, "Sedang", "Mahal"))
A3: Wisata Religi Gunung Mujur ꦒꦸꦤꦸꦁꦩꦸꦗꦸꦂ | B3: 0.017391304 | C3: 0.87717973 | D3: 0.36447339 | K3: =ABS(B3 - $G$2) | L3: =ABS(B3 - $H$2) | M3: =ABS(B3 - $I$2) | O3: =(1/K3^2) / ((1/K3^2) + (1/L3^2) + (1/M3^2)) | P3: =(1/L3^2) / ((1/K3^2) + (1/L3^2) + (1/M3^2)) | Q3: =(1/M3^2) / ((1/K3^2) + (1/L3^2) + (1/M3^2)) | S3: =IF(MAX(O3:Q3)=O3, "Murah", IF(MAX(O3:Q3)=P3, "Sedang", "Mahal"))
A4: Masjid Agung Jami' Kota Malang | B4: 0 | C4: 0.65046435 | D4: 0.42096219 | G4: =SUMPRODUCT(O2:O189^2, $B$2:$B$189) / SUMSQ(O2:O189) | H4: =SUMPRODUCT(P2:P189^2, $B$2:$B$189) / SUMSQ(P2:P189) | I4: =SUMPRODUCT(Q2:Q189^2, $B$2:$B$189) / SUMSQ(Q2:Q189) | K4: =ABS(B4 - $G$2) | L4: =ABS(B4 - $H$2) | M4: =ABS(B4 - $I$2) | O4: =(1/K4^2) / ((1/K4^2) + (1/L4^2) + (1/M4^2)) | P4: =(1/L4^2) / ((1/K4^2) + (1/L4^2) + (1/M4^2)) | Q4: =(1/M4^2) / ((1/K4^2) + (1/L4^2) + (1/M4^2)) | S4: =IF(MAX(O4:Q4)=O4, "Murah", IF(MAX(O4:Q4)=P4, "Sedang", "Mahal"))
A5: Makam Mbah Batu | B5: 0.0052173913 | C5: 0.83355797 | D5: 0.27516046 | K5: =ABS(B5 - $G$2) | L5: =ABS(B5 - $H$2) | M5: =ABS(B5 - $I$2) | O5: =(1/K5^2) / ((1/K5^2) + (1/L5^2) + (1/M5^2)) | P5: =(1/L5^2) / ((1/K5^2) + (1/L5^2) + (1/M5^2)) | Q5: =(1/M5^2) / ((1/K5^2) + (1/L5^2) + (1/M5^2)) | S5: =IF(MAX(O5:Q5)=O5, "Murah", IF(MAX(O5:Q5)=P5, "Sedang", "Mahal"))
A6: KWJ MALANG | B6: 0.0086956522 | C6: 0.64942257 | D6: 0.43294011 | K6: =ABS(B6 - $G$2) | L6: =ABS(B6 - $H$2) | M6: =ABS(B6 - $I$2) | O6: =(1/K6^2) / ((1/K6^2) + (1/L6^2) + (1/M6^2)) | P6: =(1/L6^2) / ((1/K6^2) + (1/L6^2) + (1/M6^2)) | Q6: =(1/M6^2) / ((1/K6^2) + (1/L6^2) + (1/M6^2)) | S6: =IF(MAX(O6:Q6)=O6, "Murah", IF(MAX(O6:Q6)=P6, "Sedang", "Mahal"))
A7: Pesarean Gunung Kawi | B7: 0.0052173913 | C7: 0.59117394 | D7: 0.21040039 | K7: =ABS(B7 - $G$2) | L7: =ABS(B7 - $H$2) | M7: =ABS(B7 - $I$2) | O7: =(1/K7^2) / ((1/K7^2) + (1/L7^2) + (1/M7^2)) | P7: =(1/L7^2) / ((1/K7^2) + (1/L7^2) + (1/M7^2)) | Q7: =(1/M7^2) / ((1/K7^2) + (1/L7^2) + (1/M7^2)) | S7: =IF(MAX(O7:Q7)=O7, "Murah", IF(MAX(O7:Q7)=P7, "Sedang", "Mahal"))
A8: Makam Ki Ageng Gribig | B8: 0.083478261 | C8: 0.65260383 | D8: 0.47640508 | K8: =ABS(B8 - $G$2) | L8: =ABS(B8 - $H$2) | M8: =ABS(B8 - $I$2) | O8: =(1/K8^2) / ((1/K8^2) + (1/L8^2) + (1/M8^2)) | P8: =(1/L8^2) / ((1/K8^2) + (1/L8^2) + (1/M8^2)) | Q8: =(1/M8^2) / ((1/K8^2) + (1/L8^2) + (1/M8^2)) | S8: =IF(MAX(O8:Q8)=O8, "Murah", IF(MAX(O8:Q8)=P8, "Sedang", "Mahal"))
A9: Pura Luhur Giri Arjuno | B9: 0.019130435 | C9: 0.9367701 | D9: 0.29379943 | K9: =ABS(B9 - $G$2) | L9: =ABS(B9 - $H$2) | M9: =ABS(B9 - $I$2) | O9: =(1/K9^2) / ((1/K9^2) + (1/L9^2) + (1/M9^2)) | P9: =(1/L9^2) / ((1/K9^2) + (1/L9^2) + (1/M9^2)) | Q9: =(1/M9^2) / ((1/K9^2) + (1/L9^2) + (1/M9^2)) | S9: =IF(MAX(O9:Q9)=O9, "Murah", IF(MAX(O9:Q9)=P9, "Sedang", "Mahal"))
A10: Masjid An-Nur | B10: 0.017391304 | C10: 0.67728737 | D10: 0.42060728 | K10: =ABS(B10 - $G$2) | L10: =ABS(B10 - $H$2) | M10: =ABS(B10 - $I$2) | O10: =(1/K10^2) / ((1/K10^2) + (1/L10^2) + (1/M10^2)) | P10: =(1/L10^2) / ((1/K10^2) + (1/L10^2) + (1/M10^2)) | Q10: =(1/M10^2) / ((1/K10^2) + (1/L10^2) + (1/M10^2)) | S10: =IF(MAX(O10:Q10)=O10, "Murah", IF(MAX(O10:Q10)=P10, "Sedang", "Mahal"))
A11: MAKAM MBAH JAGOPATI | B11: 0 | C11: 0.52524663 | D11: 0.46693576 | K11: =ABS(B11 - $G$2) | L11: =ABS(B11 - $H$2) | M11: =ABS(B11 - $I$2) | O11: =(1/K11^2) / ((1/K11^2) + (1/L11^2) + (1/M11^2)) | P11: =(1/L11^2) / ((1/K11^2) + (1/L11^2) + (1/M11^2)) | Q11: =(1/M11^2) / ((1/K11^2) + (1/L11^2) + (1/M11^2)) | S11: =IF(MAX(O11:Q11)=O11, "Murah", IF(MAX(O11:Q11)=P11, "Sedang", "Mahal"))
A12: Wisata Religi Sumber 9 | B12: 0.0086956522 | C12: 0.37475592 | D12: 0.29374959 | K12: =ABS(B12 - $G$2) | L12: =ABS(B12 - $H$2) | M12: =ABS(B12 - $I$2) | O12: =(1/K12^2) / ((1/K12^2) + (1/L12^2) + (1/M12^2)) | P12: =(1/L12^2) / ((1/K12^2) + (1/L12^2) + (1/M12^2)) | Q12: =(1/M12^2) / ((1/K12^2) + (1/L12^2) + (1/M12^2)) | S12: =IF(MAX(O12:Q12)=O12, "Murah", IF(MAX(O12:Q12)=P12, "Sedang", "Mahal"))
A13: Parkir mobil gratis Masjid tiban turen | B13: 0.0086956522 | C13: 0.40488439 | D13: 0.54840517 | K13: =ABS(B13 - $G$2) | L13: =ABS(B13 - $H$2) | M13: =ABS(B13 - $I$2) | O13: =(1/K13^2) / ((1/K13^2) + (1/L13^2) + (1/M13^2)) | P13: =(1/L13^2) / ((1/K13^2) + (1/L13^2) + (1/M13^2)) | Q13: =(1/M13^2) / ((1/K13^2) + (1/L13^2) + (1/M13^2)) | S13: =IF(MAX(O13:Q13)=O13, "Murah", IF(MAX(O13:Q13)=P13, "Sedang", "Mahal"))
A14: Punden Mbah Mogok | B14: 0.017391304 | C14: 0.68015327 | D14: 0.38260531 | K14: =ABS(B14 - $G$2) | L14: =ABS(B14 - $H$2) | M14: =ABS(B14 - $I$2) | O14: =(1/K14^2) / ((1/K14^2) + (1/L14^2) + (1/M14^2)) | P14: =(1/L14^2) / ((1/K14^2) + (1/L14^2) + (1/M14^2)) | Q14: =(1/M14^2) / ((1/K14^2) + (1/L14^2) + (1/M14^2)) | S14: =IF(MAX(O14:Q14)=O14, "Murah", IF(MAX(O14:Q14)=P14, "Sedang", "Mahal"))
A15: Maqam Al Habib Abdullah Bin Abdul Qadir Bilfaqih | B15: 0.034782609 | C15: 0.64070763 | D15: 0.41191521 | K15: =ABS(B15 - $G$2) | L15: =ABS(B15 - $H$2) | M15: =ABS(B15 - $I$2) | O15: =(1/K15^2) / ((1/K15^2) + (1/L15^2) + (1/M15^2)) | P15: =(1/L15^2) / ((1/K15^2) + (1/L15^2) + (1/M15^2)) | Q15: =(1/M15^2) / ((1/K15^2) + (1/L15^2) + (1/M15^2)) | S15: =IF(MAX(O15:Q15)=O15, "Murah", IF(MAX(O15:Q15)=P15, "Sedang", "Mahal"))
A16: Pura Luhur Dwijawarsa | B16: 0.18173913 | C16: 0.63156172 | D16: 0.46929098 | K16: =ABS(B16 - $G$2) | L16: =ABS(B16 - $H$2) | M16: =ABS(B16 - $I$2) | O16: =(1/K16^2) / ((1/K16^2) + (1/L16^2) + (1/M16^2)) | P16: =(1/L16^2) / ((1/K16^2) + (1/L16^2) + (1/M16^2)) | Q16: =(1/M16^2) / ((1/K16^2) + (1/L16^2) + (1/M16^2)) | S16: =IF(MAX(O16:Q16)=O16, "Murah", IF(MAX(O16:Q16)=P16, "Sedang", "Mahal"))
... A189: Wisata Air Sumber Jenon | B189: 0.017391304 | C189: 0.55152058 | D189: 0 | K189: =ABS(B189 - $G$2) | L189: =ABS(B189 - $H$2) | M189: =ABS(B189 - $I$2) | O189: =(1/K189^2) / ((1/K189^2) + (1/L189^2) + (1/M189^2)) | P189: =(1/L189^2) / ((1/K189^2) + (1/L189^2) + (1/M189^2)) | Q189: =(1/M189^2) / ((1/K189^2) + (1/L189^2) + (1/M189^2)) | S189: =IF(MAX(O189:Q189)=O189, "Murah", IF(MAX(O189:Q189)=P189, "Sedang", "Mahal"))

Sheet MAKAN HIT_FCM
A1: Nama_Tempat | B1: Estimasi_Harga | C1: Latitude | D1: Longitude | F1: PUSAT CLUSTER | G1: Cluster 1 (Murah) | H1: Cluster 2 (Sedang) | I1: Cluster 3 (Mahal) | K1: Jarak_ke_C1 | L1: Jarak_ke_C2 | M1: Jarak_ke_C3 | O1: Mu_Murah | P1: Mu_Sedang | Q1: Mu_Mahal | S1: Kategori Akhir
A2: Depot Cwimie Malang | B2: 0.022494888 | C2: 0.96613522 | D2: 0.93070142 | G2: 0.042383 | H2: 0.225442 | I2: 0.858021 | K2: =ABS(B2 - $G$2) | L2: =ABS(B2 - $H$2) | M2: =ABS(B2 - $I$2) | O2: =(1/K2^2) / ((1/K2^2) + (1/L2^2) + (1/M2^2)) | P2: =(1/L2^2) / ((1/K2^2) + (1/L2^2) + (1/M2^2)) | Q2: =(1/M2^2) / ((1/K2^2) + (1/L2^2) + (1/M2^2)) | S2: =IF(MAX(O2:Q2)=O2, "Murah", IF(MAX(O2:Q2)=P2, "Sedang", "Mahal"))
A3: Depot Rawon Malang "MM" | B3: 0.19631902 | C3: 0.98531679 | D3: 0.75888462 | K3: =ABS(B3 - $G$2) | L3: =ABS(B3 - $H$2) | M3: =ABS(B3 - $I$2) | O3: =(1/K3^2) / ((1/K3^2) + (1/L3^2) + (1/M3^2)) | P3: =(1/L3^2) / ((1/K3^2) + (1/L3^2) + (1/M3^2)) | Q3: =(1/M3^2) / ((1/K3^2) + (1/L3^2) + (1/M3^2)) | S3: =IF(MAX(O3:Q3)=O3, "Murah", IF(MAX(O3:Q3)=P3, "Sedang", "Mahal"))
A4: Depot J-One | B4: 0.16155419 | C4: 0.9744903 | D4: 0.98941494 | G4: =SUMPRODUCT(O2:O492^2, $B$2:$B$492) / SUMSQ(O2:O492) | H4: =SUMPRODUCT(P2:P492^2, $B$2:$B$492) / SUMSQ(P2:P492) | I4: =SUMPRODUCT(Q2:Q492^2, $B$2:$B$492) / SUMSQ(Q2:Q492) | K4: =ABS(B4 - $G$2) | L4: =ABS(B4 - $H$2) | M4: =ABS(B4 - $I$2) | O4: =(1/K4^2) / ((1/K4^2) + (1/L4^2) + (1/M4^2)) | P4: =(1/L4^2) / ((1/K4^2) + (1/L4^2) + (1/M4^2)) | Q4: =(1/M4^2) / ((1/K4^2) + (1/L4^2) + (1/M4^2)) | S4: =IF(MAX(O4:Q4)=O4, "Murah", IF(MAX(O4:Q4)=P4, "Sedang", "Mahal"))
A5: Depot Gang Djangkrik Manyar Kertoarjo Surabaya | B5: 0.48261759 | C5: 0.9827141 | D5: 0.90091692 | K5: =ABS(B5 - $G$2) | L5: =ABS(B5 - $H$2) | M5: =ABS(B5 - $I$2) | O5: =(1/K5^2) / ((1/K5^2) + (1/L5^2) + (1/M5^2)) | P5: =(1/L5^2) / ((1/K5^2) + (1/L5^2) + (1/M5^2)) | Q5: =(1/M5^2) / ((1/K5^2) + (1/L5^2) + (1/M5^2)) | S5: =IF(MAX(O5:Q5)=O5, "Murah", IF(MAX(O5:Q5)=P5, "Sedang", "Mahal"))
A6: Depot Gang Djangkrik Kawi Atas Malang | B6: 0.23517382 | C6: 0.14141133 | D6: 0.34368444 | K6: =ABS(B6 - $G$2) | L6: =ABS(B6 - $H$2) | M6: =ABS(B6 - $I$2) | O6: =(1/K6^2) / ((1/K6^2) + (1/L6^2) + (1/M6^2)) | P6: =(1/L6^2) / ((1/K6^2) + (1/L6^2) + (1/M6^2)) | Q6: =(1/M6^2) / ((1/K6^2) + (1/L6^2) + (1/M6^2)) | S6: =IF(MAX(O6:Q6)=O6, "Murah", IF(MAX(O6:Q6)=P6, "Sedang", "Mahal"))
A7: Depot Pak Bas | B7: 0.09202454 | C7: 0.98162633 | D7: 0.90661563 | K7: =ABS(B7 - $G$2) | L7: =ABS(B7 - $H$2) | M7: =ABS(B7 - $I$2) | O7: =(1/K7^2) / ((1/K7^2) + (1/L7^2) + (1/M7^2)) | P7: =(1/L7^2) / ((1/K7^2) + (1/L7^2) + (1/M7^2)) | Q7: =(1/M7^2) / ((1/K7^2) + (1/L7^2) + (1/M7^2)) | S7: =IF(MAX(O7:Q7)=O7, "Murah", IF(MAX(O7:Q7)=P7, "Sedang", "Mahal"))
A8: Depot Ny Kim | B8: 0.11042945 | C8: 0.96209235 | D8: 0.9158228 | K8: =ABS(B8 - $G$2) | L8: =ABS(B8 - $H$2) | M8: =ABS(B8 - $I$2) | O8: =(1/K8^2) / ((1/K8^2) + (1/L8^2) + (1/M8^2)) | P8: =(1/L8^2) / ((1/K8^2) + (1/L8^2) + (1/M8^2)) | Q8: =(1/M8^2) / ((1/K8^2) + (1/L8^2) + (1/M8^2)) | S8: =IF(MAX(O8:Q8)=O8, "Murah", IF(MAX(O8:Q8)=P8, "Sedang", "Mahal"))
A9: Depot Gang Djangkrik | B9: 0.23517382 | C9: 0.16387244 | D9: 0.4143366 | K9: =ABS(B9 - $G$2) | L9: =ABS(B9 - $H$2) | M9: =ABS(B9 - $I$2) | O9: =(1/K9^2) / ((1/K9^2) + (1/L9^2) + (1/M9^2)) | P9: =(1/L9^2) / ((1/K9^2) + (1/L9^2) + (1/M9^2)) | Q9: =(1/M9^2) / ((1/K9^2) + (1/L9^2) + (1/M9^2)) | S9: =IF(MAX(O9:Q9)=O9, "Murah", IF(MAX(O9:Q9)=P9, "Sedang", "Mahal"))
A10: Depot Tanjung Api Malang | B10: 0.11166871 | C10: 0.15394213 | D10: 0.36890459 | K10: =ABS(B10 - $G$2) | L10: =ABS(B10 - $H$2) | M10: =ABS(B10 - $I$2) | O10: =(1/K10^2) / ((1/K10^2) + (1/L10^2) + (1/M10^2)) | P10: =(1/L10^2) / ((1/K10^2) + (1/L10^2) + (1/M10^2)) | Q10: =(1/M10^2) / ((1/K10^2) + (1/L10^2) + (1/M10^2)) | S10: =IF(MAX(O10:Q10)=O10, "Murah", IF(MAX(O10:Q10)=P10, "Sedang", "Mahal"))
A11: Depot Sari Rasa | B11: 0.13087935 | C11: 0.15348314 | D11: 0.39832288 | K11: =ABS(B11 - $G$2) | L11: =ABS(B11 - $H$2) | M11: =ABS(B11 - $I$2) | O11: =(1/K11^2) / ((1/K11^2) + (1/L11^2) + (1/M11^2)) | P11: =(1/L11^2) / ((1/K11^2) + (1/L11^2) + (1/M11^2)) | Q11: =(1/M11^2) / ((1/K11^2) + (1/L11^2) + (1/M11^2)) | S11: =IF(MAX(O11:Q11)=O11, "Murah", IF(MAX(O11:Q11)=P11, "Sedang", "Mahal"))
A12: Depot Kayutangan | B12: 0.079754601 | C12: 0.14020052 | D12: 0.38439294 | K12: =ABS(B12 - $G$2) | L12: =ABS(B12 - $H$2) | M12: =ABS(B12 - $I$2) | O12: =(1/K12^2) / ((1/K12^2) + (1/L12^2) + (1/M12^2)) | P12: =(1/L12^2) / ((1/K12^2) + (1/L12^2) + (1/M12^2)) | Q12: =(1/M12^2) / ((1/K12^2) + (1/L12^2) + (1/M12^2)) | S12: =IF(MAX(O12:Q12)=O12, "Murah", IF(MAX(O12:Q12)=P12, "Sedang", "Mahal"))
A13: Depot Malang Kuliner | B13: 0.13844581 | C13: 0.15485721 | D13: 0.42021215 | K13: =ABS(B13 - $G$2) | L13: =ABS(B13 - $H$2) | M13: =ABS(B13 - $I$2) | O13: =(1/K13^2) / ((1/K13^2) + (1/L13^2) + (1/M13^2)) | P13: =(1/L13^2) / ((1/K13^2) + (1/L13^2) + (1/M13^2)) | Q13: =(1/M13^2) / ((1/K13^2) + (1/L13^2) + (1/M13^2)) | S13: =IF(MAX(O13:Q13)=O13, "Murah", IF(MAX(O13:Q13)=P13, "Sedang", "Mahal"))
A14: Depot Djempolan | B14: 0.042944785 | C14: 0.1265576 | D14: 0.39990156 | K14: =ABS(B14 - $G$2) | L14: =ABS(B14 - $H$2) | M14: =ABS(B14 - $I$2) | O14: =(1/K14^2) / ((1/K14^2) + (1/L14^2) + (1/M14^2)) | P14: =(1/L14^2) / ((1/K14^2) + (1/L14^2) + (1/M14^2)) | Q14: =(1/M14^2) / ((1/K14^2) + (1/L14^2) + (1/M14^2)) | S14: =IF(MAX(O14:Q14)=O14, "Murah", IF(MAX(O14:Q14)=P14, "Sedang", "Mahal"))
A15: Depot 200 | B15: 0.032719836 | C15: 0.18758468 | D15: 0.29504756 | K15: =ABS(B15 - $G$2) | L15: =ABS(B15 - $H$2) | M15: =ABS(B15 - $I$2) | O15: =(1/K15^2) / ((1/K15^2) + (1/L15^2) + (1/M15^2)) | P15: =(1/L15^2) / ((1/K15^2) + (1/L15^2) + (1/M15^2)) | Q15: =(1/M15^2) / ((1/K15^2) + (1/L15^2) + (1/M15^2)) | S15: =IF(MAX(O15:Q15)=O15, "Murah", IF(MAX(O15:Q15)=P15, "Sedang", "Mahal"))
A16: Gudeg Bu Toegijo | B16: 0.11656442 | C16: 0.97328457 | D16: 0.92490839 | K16: =ABS(B16 - $G$2) | L16: =ABS(B16 - $H$2) | M16: =ABS(B16 - $I$2) | O16: =(1/K16^2) / ((1/K16^2) + (1/L16^2) + (1/M16^2)) | P16: =(1/L16^2) / ((1/K16^2) + (1/L16^2) + (1/M16^2)) | Q16: =(1/M16^2) / ((1/K16^2) + (1/L16^2) + (1/M16^2)) | S16: =IF(MAX(O16:Q16)=O16, "Murah", IF(MAX(O16:Q16)=P16, "Sedang", "Mahal"))
... A492: Nasi Babat Kampung Malang Surabaya | B492: 0.059304703 | C492: 0.99492797 | D492: 0.77069946 | K492: =ABS(B492 - $G$2) | L492: =ABS(B492 - $H$2) | M492: =ABS(B492 - $I$2) | O492: =(1/K492^2) / ((1/K492^2) + (1/L492^2) + (1/M492^2)) | P492: =(1/L492^2) / ((1/K492^2) + (1/L492^2) + (1/M492^2)) | Q492: =(1/M492^2) / ((1/K492^2) + (1/L492^2) + (1/M492^2)) | S492: =IF(MAX(O492:Q492)=O492, "Murah", IF(MAX(O492:Q492)=P492, "Sedang", "Mahal"))

Sheet HOTEL_KAT
A1: A | B1: B | C1: C | D1: D | E1: E | F1: F
A2: Id_Tempat | B2: Nama_Tempat | C2: Estimasi_Harga | D2: Latitude | E2: Longitude | F2: KATEGORI_HARGA
A3: 67 | B3: Villa Malang MARRY IND Puncak Buring | C3: 3644629 | D3: -8.0107985 | E3: 112.6552 | F3: Mahal
A4: 73 | B4: Little Creek Lodge | C4: 2000000 | D4: -7.94385 | E4: 112.63385 | F4: Mahal
A5: 100 | B5: Vila Bumi Madinah Dau-Malang | C5: 2892562 | D5: -7.9349599 | E5: 112.57217 | F5: Mahal
A6: 103 | B6: Villa Samawa | C6: 2500000 | D6: -7.9312301 | E6: 112.62245 | F6: Mahal
A7: 106 | B7: Villa Bromo | C7: 2936118 | D7: -7.9658499 | E7: 112.58472 | F7: Mahal
A8: 110 | B8: Villa Malang Puncak Buring | C8: 3644629 | D8: -8.01192 | E8: 112.65491 | F8: Mahal
A9: 322 | B9: Djoglo Luxury Bungalow | C9: 2342884 | D9: -7.9319402 | E9: 112.66419 | F9: Mahal
A10: 1 | B10: SUPER OYO Flagship 90502 Holistay Malang New | C10: 347052 | D10: -7.9368115 | E10: 112.64869 | F10: Murah
A11: 2 | B11: Hotel OYO 709 Menjangan Residen | C11: 51823 | D11: -8.0040178 | E11: 112.61394 | F11: Murah
A12: 3 | B12: Super OYO 1376 Kina Family Residence Syariah | C12: 158466 | D12: -7.943296 | E12: 112.60138 | F12: Murah
A13: 4 | B13: OYO Flagship 90723 Khalifi House Malang | C13: 220540 | D13: -7.9694153 | E13: 112.66841 | F13: Murah
A14: 5 | B14: OYO 94769 Griya Djati Syariah 2 | C14: 123967 | D14: -7.9859953 | E14: 112.65978 | F14: Murah
... A365: 324 | B365: Ijen Suites Resort & Convention Malang | C365: 721333 | D365: -7.9806558 | E365: 112.61544 | F365: Sedang

Sheet WISATA_KAT
A1: Id_Tempat | B1: Nama_Tempat | C1: Harga_Tiket | D1: Latitude | E1: Longitude | F1: KATEGORI_HARGA
A2: 8 | B2: Pura Luhur Giri Arjuno | C2: 2000 | D2: -7.7852789 | E2: 112.54731 | F2: Mahal
A3: 22 | B3: Bukit Nirwana | C3: 10000 | D3: -7.8617098 | E3: 112.46002 | F3: Mahal
A4: 28 | B4: Air Terjun Coban Supit Urang | C4: 0 | D4: -7.7910044 | E4: 112.46035 | F4: Mahal
A5: 32 | B5: Wisata Gunung Kombang | C5: 3000 | D5: -8.3865186 | E5: 112.42574 | F5: Mahal
A6: 54 | B6: Agrowisata Telaga Madiredo | C6: 5000 | D6: -7.8249722 | E6: 112.45981 | F6: Mahal
A7: 57 | B7: Desa Wisata Gubugklakah ꦒꦸꦧꦸꦏ꧀ꦏ꧀ꦭꦏꦃ | C7: 3000 | D7: -8.0288179 | E7: 112.82347 | F7: Mahal
A8: 68 | B8: Bukit Waung | C8: 48000 | D8: -8.3488921 | E8: 112.36778 | F8: Mahal
A9: 77 | B9: Air Terjun Grojogan Sewu Pujon | C9: 11000 | D9: -7.8664128 | E9: 112.42335 | F9: Mahal
A10: 86 | B10: Meeting Point Pujon Rafting | C10: 10000 | D10: -7.8396791 | E10: 112.44977 | F10: Mahal
A11: 97 | B11: Petik Apel Green Garden | C11: 0 | D11: -7.8230867 | E11: 112.52902 | F11: Mahal
A12: 100 | B12: Wisata Coban Rondo | C12: 5000 | D12: -7.8703079 | E12: 112.48157 | F12: Mahal
A13: 108 | B13: Museum Angkut | C13: 5000 | D13: -7.8790652 | E13: 112.51872 | F13: Mahal
... A189: 174 | B189: Pemandian Belakang Wendit Wakaf | C189: 10000 | D189: -7.9553541 | E189: 112.67419 | F189: Sedang

Sheet MAKAN_KAT
A1: Id_Tempat | B1: Nama_Tempat | C1: Estimasi_Harga | D1: Latitude | E1: Longitude | F1: KATEGORI_HARGA
A2: 26 | B2: Harmoni Cafe & Resto l Since 2010 | C2: 144714 | D2: -7.9744753 | E2: 112.62754 | F2: Mahal
A3: 32 | B3: Javanine Resto | C3: 234522 | D3: -7.9672115 | E3: 112.6209 | F3: Mahal
A4: 36 | B4: Resto Sambat Luwe | C4: 237345 | D4: -8.0221352 | E4: 112.64109 | F4: Mahal
A5: 71 | B5: New Hongkong Restaurant - Arif Rahman Hakim | C5: 208503 | D5: -7.9814911 | E5: 112.62912 | F5: Mahal
A6: 91 | B6: Melati Restaurant | C6: 246546 | D6: -7.9770541 | E6: 112.63287 | F6: Mahal
A7: 192 | B7: Dialoogi Signature Restaurant Malang | C7: 171684 | D7: -7.960162 | E7: 112.62234 | F7: Mahal
A8: 1 | B8: Depot Gang Djangkrik Kawi Atas Malang | C8: 27049 | D8: -7.9753699 | E8: 112.61928 | F8: Murah
A9: 2 | B9: Depot Gang Djangkrik | C9: 12314 | D9: -7.9568232 | E9: 112.63846 | F9: Murah
A10: 3 | B10: Depot Tanjung Api Malang | C10: 16273 | D10: -7.9650229 | E10: 112.62613 | F10: Murah
A11: 4 | B11: Depot Sari Rasa | C11: 15930 | D11: -7.9654019 | E11: 112.63411 | F11: Murah
A12: 5 | B12: Depot Kayutangan | C12: 22792 | D12: -7.9763697 | E12: 112.63033 | F12: Murah
A13: 6 | B13: Depot Malang Kuliner | C13: 21374 | D13: -7.9642673 | E13: 112.64005 | F13: Murah
... A506: 505 | B506: Partikular Coffee | C506: 62744 | D506: -7.9810387 | E506: 112.62785 | F506: Sedang

Sheet DEMO_PAKET
B2: FORMULIR PENCARIAN PAKET WISATA
B4: Total Anggaran (Rupiah): | C4: 4500000
B5: Jumlah Peserta (Orang): | C5: 2
B6: Durasi Liburan (Hari): | C6: 2
B8: KALKULASI OTOMATIS
B9: Budget Per Orang | C9: =C4/C5 | D9: (Total Anggaran ÷ Jumlah Peserta)
B10: Kebutuhan Kamar Hotel | C10: =ROUNDUP(C5/2, 0) | D10: (1 kamar maks 2 orang)
B11: Total Kebutuhan Makan | C11: =C5 * C6 * 3 | D11: (Peserta Hari 3 kali makan)
B13: STRATEGI ALOKASI BUDGET (berdasarkan Marigallang et al., 2024)
B14: Catatan: Pembagian budget berbeda untuk setiap paket
B16: Komponen | C16: PAKET HEMAT | D16: PAKET BALANCED | E16: PAKET PREMIUM
B17: Hotel (% dari total budget) | C17: 12% | D17: 16% | E17: 25%
B18: Budget Hotel | C18: =C4*12% | D18: =C4*16% | E18: =C4*25%
B19: Budget Hotel per Malam | C19: =C18/C6/C10 | D19: =D18/C6/C10 | E19: =E18/C6/C10
B21: Wisata (% dari total budget) | C21: 15% | D21: 22% | E21: 25%
B22: Budget Wisata | C22: =C4*15% | D22: =C4*22% | E22: =C4*25%
B23: Budget Wisata per Orang | C23: =C22/C5 | D23: =D22/C5 | E23: =E22/C5
B25: Makan (% dari total budget) | C25: 25% | D25: 30% | E25: 35%
B26: Budget Makan | C26: =C4*25% | D26: =C4*30% | E26: =C4*35%
B27: Budget Makan per Porsi | C27: =C26/C11 | D27: =D26/C11 | E27: =E26/C11
B29: Total Budget Dialokasikan | C29: =C18+C22+C26 | D29: =D18+D22+D26 | E29: =E18+E22+E26
B30: Sisa Budget (Buffer) | C30: =C4-C29 | D30: =C4-D29 | E30: =C4-E29
B32: REKOMENDASI PAKET WISATA
B33: Catatan: Rekomendasi berdasarkan hasil clustering FCM dan budget allocation
B35: Komponen | C35: PAKET HEMAT | D35: PAKET BALANCED | E35: PAKET PREMIUM
B37: HOTEL
B38: Nama Hotel | C38: =INDEX(HOTEL_KAT!$B:$B, MATCH("Murah", HOTEL_KAT!$F:$F, 0)) | D38: =INDEX(HOTEL_KAT!B:B, SUMPRODUCT(MAX((HOTEL_KAT!F:F="Sedang")*(HOTEL_KAT!C:C<=D19)*(HOTEL_KAT!C:C>0)*ROW(HOTEL_KAT!C:C)))) | E38: =INDEX(HOTEL_KAT!B:B, SUMPRODUCT(MAX((HOTEL_KAT!F:F="Mahal")*(HOTEL_KAT!C:C>0)*ROW(HOTEL_KAT!C:C))))
B39: Harga per Malam | C39: =INDEX(HOTEL_KAT!$C:$C, MATCH("Murah", HOTEL_KAT!$F:$F, 0)) | D39: =INDEX(HOTEL_KAT!$C:$C, SUMPRODUCT(MAX((HOTEL_KAT!$F:$F="Sedang")*(HOTEL_KAT!$C:$C<=D19)*(HOTEL_KAT!$C:$C>0)*ROW(HOTEL_KAT!$C:$C)))) | E39: =INDEX(HOTEL_KAT!$C:$C, SUMPRODUCT(MAX((HOTEL_KAT!$F:$F="Mahal")*(HOTEL_KAT!$C:$C>0)*ROW(HOTEL_KAT!$C:$C))))
B40: Total Biaya Hotel | C40: =C39*C6*C10 | D40: =D39*C6*C10 | E40: =E39*C6*C10
B41: Koordinat Hotel (Lat, Long) | C41: =INDEX(HOTEL_KAT!$D:$D, MATCH(C38, HOTEL_KAT!$B:$B, 0)) | D41: =INDEX(HOTEL_KAT!$D:$D, MATCH(D38, HOTEL_KAT!$B:$B, 0)) | E41: =INDEX(HOTEL_KAT!$D:$D, MATCH(E38, HOTEL_KAT!$B:$B, 0))
C42: =INDEX(HOTEL_KAT!$E:$E, MATCH(C38, HOTEL_KAT!$B:$B, 0)) | D42: =INDEX(HOTEL_KAT!$E:$E, MATCH(D38, HOTEL_KAT!$B:$B, 0)) | E42: =INDEX(HOTEL_KAT!$E:$E, MATCH(E38, HOTEL_KAT!$B:$B, 0))
B43: WISATA
B44: Nama Wisata | C44: =INDEX(WISATA_KAT!$B:$B, MATCH("Murah", WISATA_KAT!$F:$F, 0)) | D44: =INDEX(WISATA_KAT!B:B, SUMPRODUCT(MAX((WISATA_KAT!F:F="Sedang")*(WISATA_KAT!C:C<=D23)*(WISATA_KAT!C:C>0)*ROW(WISATA_KAT!C:C)))) | E44: =INDEX(WISATA_KAT!B:B, SUMPRODUCT(MAX((WISATA_KAT!F:F="Mahal")*(WISATA_KAT!C:C>0)*ROW(WISATA_KAT!C:C))))
B45: Harga Tiket per Orang | C45: =INDEX(WISATA_KAT!$C:$C, MATCH("Murah", WISATA_KAT!$F:$F, 0)) | D45: =INDEX(WISATA_KAT!$C:$C, SUMPRODUCT(MAX((WISATA_KAT!$F:$F="Sedang")*(WISATA_KAT!$C:$C<=D23)*(WISATA_KAT!$C:$C>0)*ROW(WISATA_KAT!$C:$C)))) | E45: =INDEX(WISATA_KAT!$C:$C, SUMPRODUCT(MAX((WISATA_KAT!$F:$F="Mahal")*(WISATA_KAT!$C:$C>0)*ROW(WISATA_KAT!$C:$C))))
B46: Total Biaya Wisata | C46: =C45*C5 | D46: =D45*C5 | E46: =E45*C5
B47: Status Budget Wisata | C47: =IF(C46<=C22, " Sesuai Budget", " Melebihi Budget") | D47: =IF(D46<=D22, " Sesuai Budget", " Melebihi Budget") | E47: =IF(E46<=E22, " Sesuai Budget", " Melebihi Budget")
B48: Koordinat Wisata (Lat, Long) | C48: =INDEX(WISATA_KAT!$D:$D, MATCH(C44, WISATA_KAT!$B:$B, 0)) | D48: =INDEX(WISATA_KAT!$D:$D, MATCH(D44, WISATA_KAT!$B:$B, 0)) | E48: =INDEX(WISATA_KAT!$D:$D, MATCH(E44, WISATA_KAT!$B:$B, 0))
C49: =INDEX(WISATA_KAT!$E:$E, MATCH(C44, WISATA_KAT!$B:$B, 0)) | D49: =INDEX(WISATA_KAT!$E:$E, MATCH(D44, WISATA_KAT!$B:$B, 0)) | E49: =INDEX(WISATA_KAT!$E:$E, MATCH(E44, WISATA_KAT!$B:$B, 0))
B50: Nama Tempat Makan | C50: =INDEX(MAKAN_KAT!$B:$B, MATCH("Murah", MAKAN_KAT!$F:$F, 0)) | D50: =INDEX(MAKAN_KAT!B:B, SUMPRODUCT(MAX((MAKAN_KAT!F:F="Sedang")*(MAKAN_KAT!C:C<=D27)*(MAKAN_KAT!C:C>0)*ROW(MAKAN_KAT!C:C)))) | E50: =INDEX(MAKAN_KAT!B:B, SUMPRODUCT(MAX((MAKAN_KAT!F:F="Mahal")*(MAKAN_KAT!C:C>0)*ROW(MAKAN_KAT!C:C))))
B51: Harga per Porsi | C51: =INDEX(MAKAN_KAT!$C:$C, MATCH("Murah", MAKAN_KAT!$F:$F, 0)) | D51: =INDEX(MAKAN_KAT!$C:$C, SUMPRODUCT(MAX((MAKAN_KAT!$F:$F="Sedang")*(MAKAN_KAT!$C:$C<=D27)*(MAKAN_KAT!$C:$C>0)*ROW(MAKAN_KAT!$C:$C)))) | E51: =INDEX(MAKAN_KAT!$C:$C, SUMPRODUCT(MAX((MAKAN_KAT!$F:$F="Mahal")*(MAKAN_KAT!$C:$C>0)*ROW(MAKAN_KAT!$C:$C))))
...
