Workbook

Sheet Dashboard
A1: SISTEM SIMULASI MATEMATIS REKOMENDASI PAKET WISATA
A4: INPUT PARAMETER SIMULASI (Dapat Diedit) | E4: RUJUKAN RUMUS SKRIPSI (BAB II)
A5: Total Anggaran Liburan (Budget) | C5: 1500000 | E5: [Persamaan 2.1] | F5: FCM Membership Constraint: sum_k(u_ik) = 1
A6: Jumlah Peserta (Orang) | C6: 2 | E6: [Persamaan 2.2] | F6: Pusat Klaster (Centroid v_k) Update Formula
A7: Durasi Perjalanan (Hari) | C7: 2 | E7: [Persamaan 2.3] | F7: Euclidean Distance: d_ik = ||x_i - v_k||
A8: Rasio Skema Inisialisasi Centroid (A-E) | C8: B | E8: [Persamaan 2.4] | F8: Membership Degree Update: u_ik = f(d_ik/d_ij)
A9: ID Tempat Wisata Pilihan Utama (Locked) | C9: 1 | E9: [Persamaan 2.6] | F9: Total Intra-Cluster Variance (Sigma)
E10: [Persamaan 2.7] | F10: Minimum Centroid Separation (sep)
E11: [Persamaan 2.8] | F11: Xie-Beni Index (XB) = Sigma / (n * sep)
A13: ALOKASI BREAKDOWN ANGGARAN PROPORSIONAL (KONDISI BUDGET-ANCHORED)
A15: Komponen Utama | B15: Rasio (%) | C15: Total Alokasi (Rp) | D15: Satuan Unit | G15: Keterangan Rumus
A16: Akomodasi (Hotel) | B16: 0.4 | C16: =C5*0.4 | D16: night/room | E16: =IF(OR(C6=0,C7=1),0,C16/(MAX(C7-1,1)*ROUNDUP(C6/2,0))) | G16: Formula: 40% Budget total / (Malam * Kamar)
A17: Wisata (Tiket Masuk) | B17: 0.15 | C17: =C5*0.15 | D17: person | E17: =IF(C6=0,0,C17/C6) | G17: Formula: 15% Budget total / Orang
A18: Kuliner (Konsumsi) | B18: 0.2 | C18: =C5*0.2 | D18: portion/meal | E18: =IF(OR(C6=0,C7=0),0,C18/(C6*3*C7)) | G18: Formula: 20% Budget total / (Orang * 3 Makan * Hari)
A19: Transportasi (Mobilitas) | B19: 0.25 | C19: =C5*0.25 | D19: total allowance | E19: =C19 | G19: Formula: 25% Budget total (Cadangan Spasial)
A20: TOTAL ANGGARAN | B20: =SUM(B16:B19) | C20: =SUM(C16:C19) | E20: Seluruh komponen dihitung menggunakan formula Excel dinamis.

Sheet Dataset_Wisata
A1: PRE-PROCESSING & CLUSTERING FUZZY C-MEANS - WISATA
A4: METADATA & PARAMETER ALGORITMA | E4: PUSAT KLASTER (CENTROID FINAL) - PERSAMAAN [2.2]
A5: Banyak Sampel (n) | C5: =COUNTA(B12:B622) | E5: Kelas Klaster | F5: Standard Centroid (Formula) | G5: Budget Centroid (Formula) | H5: Target Anchor (Rp)
A6: Fuzzifier (m) | C6: 2 | E6: MURAH / HEMAT | F6: =IF(SUMSQ(K12:K622)=0, 0, SUMPRODUCT(K12:K622, K12:K622, E12:E622) / SUMSQ(K12:K622)) | G6: =IF(SUMSQ(R12:R622)=0, 0, SUMPRODUCT(R12:R622, R12:R622, E12:E622) / SUMSQ(R12:R622)) | H6: ='Dashboard'!$E$17 * 0.6
A7: Epsilon Toleransi (e) | C7: 1e-05 | E7: SEDANG / BALANCED | F7: =IF(SUMSQ(L12:L622)=0, 0, SUMPRODUCT(L12:L622, L12:L622, E12:E622) / SUMSQ(L12:L622)) | G7: =IF(SUMSQ(S12:S622)=0, 0, SUMPRODUCT(S12:S622, S12:S622, E12:E622) / SUMSQ(S12:S622)) | H7: ='Dashboard'!$E$17 * 1.0
A8: Jumlah Iterasi Std (t) | C8: 50 | E8: MAHAL / PREMIUM | F8: =IF(SUMSQ(M12:M622)=0, 0, SUMPRODUCT(M12:M622, M12:M622, E12:E622) / SUMSQ(M12:M622)) | G8: =IF(SUMSQ(T12:T622)=0, 0, SUMPRODUCT(T12:T622, T12:T622, E12:E622) / SUMSQ(T12:T622)) | H8: ='Dashboard'!$E$17 * 1.4
A9: Jumlah Iterasi Bgt (t) | C9: 44
A10: ID Tempat | B10: Nama Tempat | C10: Latitude | D10: Longitude | E10: Harga (Rp) | F10: Rating | G10: Jumlah Ulasan | H10: Kategori | I10: Jarak Target (km) | J10: Estimasi Ongkir (Rp) | K10: U_Hemat (Std) | L10: U_Balanced (Std) | M10: U_Premium (Std) | N10: Dist_Hemat (Std) | O10: Dist_Balanced (Std) | P10: Dist_Premium (Std) | Q10: Cluster (Std) | R10: U_Hemat (Bgt) | S10: U_Balanced (Bgt) | T10: U_Premium (Bgt) | U10: Dist_Hemat (Bgt) | V10: Dist_Balanced (Bgt) | W10: Dist_Premium (Bgt) | X10: Cluster (Bgt)
A12: 1 | B12: Air Terjun Grojogan Sewu Pujon | C12: -7.8664128 | D12: 112.42335 | E12: 2000 | F12: 4.4 | G12: 1141 | H12: Wisata Umum | I12: =6371 * 2 * ASIN(SQRT(SIN(RADIANS((C12) - INDEX('Dataset_Wisata'!$C$12:$C$622, MATCH('Dashboard'!$C$9, 'Dataset_Wisata'!$A$12:$A$622, 0)))/2)^2 + COS(RADIANS(INDEX('Dataset_Wisata'!$C$12:$C$622, MATCH('Dashboard'!$C$9, 'Dataset_Wisata'!$A$12:$A$622, 0)))) * COS(RADIANS(C12)) * SIN(RADIANS((D12) - INDEX('Dataset_Wisata'!$D$12:$D$622, MATCH('Dashboard'!$C$9, 'Dataset_Wisata'!$A$12:$A$622, 0)))/2)^2)) * 1.3 | J12: =ROUND(I12 * IF('Dashboard'!$C$6<=1, 2250, IF('Dashboard'!$C$6<=4, 5150, 6000)), 0) | K12: 0.9745968 | L12: 0.023688567 | M12: 0.0017146297 | N12: =ABS(E12-$F$6) | O12: =ABS(E12-$F$7) | P12: =ABS(E12-$F$8) | Q12: =IF(K12>=MAX(L12,M12), "Hemat", IF(L12>=M12, "Balanced", "Premium")) | R12: 0.97459681 | S12: 0.023688564 | T12: 0.00171463 | U12: =ABS(E12-$G$6) | V12: =ABS(E12-$G$7) | W12: =ABS(E12-$G$8) | X12: =IF(R12>=MAX(S12,T12), "Hemat", IF(S12>=T12, "Balanced", "Premium"))
A13: 2 | B13: Waduk selorejo | C13: -7.878545 | D13: 112.3625 | E13: 20000 | F13: 4.6 | G13: 38 | H13: Taman · 49C7+J3W | I13: =6371 * 2 * ASIN(SQRT(SIN(RADIANS((C13) - INDEX('Dataset_Wisata'!$C$12:$C$622, MATCH('Dashboard'!$C$9, 'Dataset_Wisata'!$A$12:$A$622, 0)))/2)^2 + COS(RADIANS(INDEX('Dataset_Wisata'!$C$12:$C$622, MATCH('Dashboard'!$C$9, 'Dataset_Wisata'!$A$12:$A$622, 0)))) * COS(RADIANS(C13)) * SIN(RADIANS((D13) - INDEX('Dataset_Wisata'!$D$12:$D$622, MATCH('Dashboard'!$C$9, 'Dataset_Wisata'!$A$12:$A$622, 0)))/2)^2)) * 1.3 | J13: =ROUND(I13 * IF('Dashboard'!$C$6<=1, 2250, IF('Dashboard'!$C$6<=4, 5150, 6000)), 0) | K13: 0.8862297 | L13: 0.10993294 | M13: 0.003837361 | N13: =ABS(E13-$F$6) | O13: =ABS(E13-$F$7) | P13: =ABS(E13-$F$8) | Q13: =IF(K13>=MAX(L13,M13), "Hemat", IF(L13>=M13, "Balanced", "Premium")) | R13: 0.88622975 | S13: 0.10993289 | T13: 0.0038373606 | U13: =ABS(E13-$G$6) | V13: =ABS(E13-$G$7) | W13: =ABS(E13-$G$8) | X13: =IF(R13>=MAX(S13,T13), "Hemat", IF(S13>=T13, "Balanced", "Premium"))
A14: 3 | B14: TRANS Wisata Belah Duren | C14: -7.7807735 | D14: 112.34671 | E14: 25000 | F14: 4.1 | G14: 86 | H14: TRANS Wisata Belah Duren | I14: =6371 * 2 * ASIN(SQRT(SIN(RADIANS((C14) - INDEX('Dataset_Wisata'!$C$12:$C$622, MATCH('Dashboard'!$C$9, 'Dataset_Wisata'!$A$12:$A$622, 0)))/2)^2 + COS(RADIANS(INDEX('Dataset_Wisata'!$C$12:$C$622, MATCH('Dashboard'!$C$9, 'Dataset_Wisata'!$A$12:$A$622, 0)))) * COS(RADIANS(C14)) * SIN(RADIANS((D14) - INDEX('Dataset_Wisata'!$D$12:$D$622, MATCH('Dashboard'!$C$9, 'Dataset_Wisata'!$A$12:$A$622, 0)))/2)^2)) * 1.3 | J14: =ROUND(I14 * IF('Dashboard'!$C$6<=1, 2250, IF('Dashboard'!$C$6<=4, 5150, 6000)), 0) | K14: 0.71477932 | L14: 0.27804828 | M14: 0.007172407 | N14: =ABS(E14-$F$6) | O14: =ABS(E14-$F$7) | P14: =ABS(E14-$F$8) | Q14: =IF(K14>=MAX(L14,M14), "Hemat", IF(L14>=M14, "Balanced", "Premium")) | R14: 0.71477944 | S14: 0.27804815 | T14: 0.0071724073 | U14: =ABS(E14-$G$6) | V14: =ABS(E14-$G$7) | W14: =ABS(E14-$G$8) | X14: =IF(R14>=MAX(S14,T14), "Hemat", IF(S14>=T14, "Balanced", "Premium"))
A15: 4 | B15: Candi Bocok | C15: -7.8386963 | D15: 112.32412 | E15: 5000 | F15: 4.7 | G15: 21 | H15: Tujuan Wisata · 586F+GJH | I15: =6371 * 2 * ASIN(SQRT(SIN(RADIANS((C15) - INDEX('Dataset_Wisata'!$C$12:$C$622, MATCH('Dashboard'!$C$9, 'Dataset_Wisata'!$A$12:$A$622, 0)))/2)^2 + COS(RADIANS(INDEX('Dataset_Wisata'!$C$12:$C$622, MATCH('Dashboard'!$C$9, 'Dataset_Wisata'!$A$12:$A$622, 0)))) * COS(RADIANS(C15)) * SIN(RADIANS((D15) - INDEX('Dataset_Wisata'!$D$12:$D$622, MATCH('Dashboard'!$C$9, 'Dataset_Wisata'!$A$12:$A$622, 0)))/2)^2)) * 1.3 | J15: =ROUND(I15 * IF('Dashboard'!$C$6<=1, 2250, IF('Dashboard'!$C$6<=4, 5150, 6000)), 0) | K15: 0.98955665 | L15: 0.0097986114 | M15: 0.00064473421 | N15: =ABS(E15-$F$6) | O15: =ABS(E15-$F$7) | P15: =ABS(E15-$F$8) | Q15: =IF(K15>=MAX(L15,M15), "Hemat", IF(L15>=M15, "Balanced", "Premium")) | R15: 0.98955665 | S15: 0.0097986114 | T15: 0.00064473437 | U15: =ABS(E15-$G$6) | V15: =ABS(E15-$G$7) | W15: =ABS(E15-$G$8) | X15: =IF(R15>=MAX(S15,T15), "Hemat", IF(S15>=T15, "Balanced", "Premium"))
A16: 5 | B16: Kasembon Park | C16: -7.781962 | D16: 112.31039 | E16: 12000 | F16: 4.4 | G16: 948 | H16: Wisata Umum | I16: =6371 * 2 * ASIN(SQRT(SIN(RADIANS((C16) - INDEX('Dataset_Wisata'!$C$12:$C$622, MATCH('Dashboard'!$C$9, 'Dataset_Wisata'!$A$12:$A$622, 0)))/2)^2 + COS(RADIANS(INDEX('Dataset_Wisata'!$C$12:$C$622, MATCH('Dashboard'!$C$9, 'Dataset_Wisata'!$A$12:$A$622, 0)))) * COS(RADIANS(C16)) * SIN(RADIANS((D16) - INDEX('Dataset_Wisata'!$D$12:$D$622, MATCH('Dashboard'!$C$9, 'Dataset_Wisata'!$A$12:$A$622, 0)))/2)^2)) * 1.3 | J16: =ROUND(I16 * IF('Dashboard'!$C$6<=1, 2250, IF('Dashboard'!$C$6<=4, 5150, 6000)), 0) | K16: 0.99533311 | L16: 0.0044409777 | M16: 0.00022591094 | N16: =ABS(E16-$F$6) | O16: =ABS(E16-$F$7) | P16: =ABS(E16-$F$8) | Q16: =IF(K16>=MAX(L16,M16), "Hemat", IF(L16>=M16, "Balanced", "Premium")) | R16: 0.99533312 | S16: 0.0044409739 | T16: 0.00022591082 | U16: =ABS(E16-$G$6) | V16: =ABS(E16-$G$7) | W16: =ABS(E16-$G$8) | X16: =IF(R16>=MAX(S16,T16), "Hemat", IF(S16>=T16, "Balanced", "Premium"))
A17: 6 | B17: Fishing Sultan Class | C17: -7.8634029 | D17: 112.37497 | E17: 5000 | F17: 4.9 | G17: 41 | H17: Tujuan Wisata ·  | I17: =6371 * 2 * ASIN(SQRT(SIN(RADIANS((C17) - INDEX('Dataset_Wisata'!$C$12:$C$622, MATCH('Dashboard'!$C$9, 'Dataset_Wisata'!$A$12:$A$622, 0)))/2)^2 + COS(RADIANS(INDEX('Dataset_Wisata'!$C$12:$C$622, MATCH('Dashboard'!$C$9, 'Dataset_Wisata'!$A$12:$A$622, 0)))) * COS(RADIANS(C17)) * SIN(RADIANS((D17) - INDEX('Dataset_Wisata'!$D$12:$D$622, MATCH('Dashboard'!$C$9, 'Dataset_Wisata'!$A$12:$A$622, 0)))/2)^2)) * 1.3 | J17: =ROUND(I17 * IF('Dashboard'!$C$6<=1, 2250, IF('Dashboard'!$C$6<=4, 5150, 6000)), 0) | K17: 0.98955665 | L17: 0.0097986114 | M17: 0.00064473421 | N17: =ABS(E17-$F$6) | O17: =ABS(E17-$F$7) | P17: =ABS(E17-$F$8) | Q17: =IF(K17>=MAX(L17,M17), "Hemat", IF(L17>=M17, "Balanced", "Premium")) | R17: 0.98955665 | S17: 0.0097986114 | T17: 0.00064473437 | U17: =ABS(E17-$G$6) | V17: =ABS(E17-$G$7) | W17: =ABS(E17-$G$8) | X17: =IF(R17>=MAX(S17,T17), "Hemat", IF(S17>=T17, "Balanced", "Premium"))
A18: 7 | B18: Candi Sapto | C18: -7.8130262 | D18: 112.32541 | E18: 5000 | F18: 4.4 | G18: 35 | H18: Tujuan Wisata ·  | I18: =6371 * 2 * ASIN(SQRT(SIN(RADIANS((C18) - INDEX('Dataset_Wisata'!$C$12:$C$622, MATCH('Dashboard'!$C$9, 'Dataset_Wisata'!$A$12:$A$622, 0)))/2)^2 + COS(RADIANS(INDEX('Dataset_Wisata'!$C$12:$C$622, MATCH('Dashboard'!$C$9, 'Dataset_Wisata'!$A$12:$A$622, 0)))) * COS(RADIANS(C18)) * SIN(RADIANS((D18) - INDEX('Dataset_Wisata'!$D$12:$D$622, MATCH('Dashboard'!$C$9, 'Dataset_Wisata'!$A$12:$A$622, 0)))/2)^2)) * 1.3 | J18: =ROUND(I18 * IF('Dashboard'!$C$6<=1, 2250, IF('Dashboard'!$C$6<=4, 5150, 6000)), 0) | K18: 0.98955665 | L18: 0.0097986114 | M18: 0.00064473421 | N18: =ABS(E18-$F$6) | O18: =ABS(E18-$F$7) | P18: =ABS(E18-$F$8) | Q18: =IF(K18>=MAX(L18,M18), "Hemat", IF(L18>=M18, "Balanced", "Premium")) | R18: 0.98955665 | S18: 0.0097986114 | T18: 0.00064473437 | U18: =ABS(E18-$G$6) | V18: =ABS(E18-$G$7) | W18: =ABS(E18-$G$8) | X18: =IF(R18>=MAX(S18,T18), "Hemat", IF(S18>=T18, "Balanced", "Premium"))
A19: 8 | B19: Wisata Bukit Gandrung, Tanggulasi | C19: -7.761606 | D19: 112.34871 | E19: 10000 | F19: 4.4 | G19: 2171 | H19: Wisata Bukit Gandrung, Tanggulasi | I19: =6371 * 2 * ASIN(SQRT(SIN(RADIANS((C19) - INDEX('Dataset_Wisata'!$C$12:$C$622, MATCH('Dashboard'!$C$9, 'Dataset_Wisata'!$A$12:$A$622, 0)))/2)^2 + COS(RADIANS(INDEX('Dataset_Wisata'!$C$12:$C$622, MATCH('Dashboard'!$C$9, 'Dataset_Wisata'!$A$12:$A$622, 0)))) * COS(RADIANS(C19)) * SIN(RADIANS((D19) - INDEX('Dataset_Wisata'!$D$12:$D$622, MATCH('Dashboard'!$C$9, 'Dataset_Wisata'!$A$12:$A$622, 0)))/2)^2)) * 1.3 | J19: =ROUND(I19 * IF('Dashboard'!$C$6<=1, 2250, IF('Dashboard'!$C$6<=4, 5150, 6000)), 0) | K19: 0.99981265 | L19: 0.00017757184 | M19: 9.7773423e-06 | N19: =ABS(E19-$F$6) | O19: =ABS(E19-$F$7) | P19: =ABS(E19-$F$8) | Q19: =IF(K19>=MAX(L19,M19), "Hemat", IF(L19>=M19, "Balanced", "Premium")) | R19: 0.99981265 | S19: 0.00017757135 | T19: 9.777318e-06 | U19: =ABS(E19-$G$6) | V19: =ABS(E19-$G$7) | W19: =ABS(E19-$G$8) | X19: =IF(R19>=MAX(S19,T19), "Hemat", IF(S19>=T19, "Balanced", "Premium"))
A20: 9 | B20: Air Terjun Coban Rondo Pujon | C20: -7.8846458 | D20: 112.47682 | E20: 5000 | F20: 4.5 | G20: 12340 | H20: Wisata Umum | I20: =6371 * 2 * ASIN(SQRT(SIN(RADIANS((C20) - INDEX('Dataset_Wisata'!$C$12:$C$622, MATCH('Dashboard'!$C$9, 'Dataset_Wisata'!$A$12:$A$622, 0)))/2)^2 + COS(RADIANS(INDEX('Dataset_Wisata'!$C$12:$C$622, MATCH('Dashboard'!$C$9, 'Dataset_Wisata'!$A$12:$A$622, 0)))) * COS(RADIANS(C20)) * SIN(RADIANS((D20) - INDEX('Dataset_Wisata'!$D$12:$D$622, MATCH('Dashboard'!$C$9, 'Dataset_Wisata'!$A$12:$A$622, 0)))/2)^2)) * 1.3 | J20: =ROUND(I20 * IF('Dashboard'!$C$6<=1, 2250, IF('Dashboard'!$C$6<=4, 5150, 6000)), 0) | K20: 0.98955665 | L20: 0.0097986114 | M20: 0.00064473421 | N20: =ABS(E20-$F$6) | O20: =ABS(E20-$F$7) | P20: =ABS(E20-$F$8) | Q20: =IF(K20>=MAX(L20,M20), "Hemat", IF(L20>=M20, "Balanced", "Premium")) | R20: 0.98955665 | S20: 0.0097986114 | T20: 0.00064473437 | U20: =ABS(E20-$G$6) | V20: =ABS(E20-$G$7) | W20: =ABS(E20-$G$8) | X20: =IF(R20>=MAX(S20,T20), "Hemat", IF(S20>=T20, "Balanced", "Premium"))
A21: 10 | B21: Taman Wisata Blendrang | C21: -7.859486 | D21: 112.36784 | E21: 10000 | F21: 4.3 | G21: 533 | H21: Taman Wisata Blendrang | I21: =6371 * 2 * ASIN(SQRT(SIN(RADIANS((C21) - INDEX('Dataset_Wisata'!$C$12:$C$622, MATCH('Dashboard'!$C$9, 'Dataset_Wisata'!$A$12:$A$622, 0)))/2)^2 + COS(RADIANS(INDEX('Dataset_Wisata'!$C$12:$C$622, MATCH('Dashboard'!$C$9, 'Dataset_Wisata'!$A$12:$A$622, 0)))) * COS(RADIANS(C21)) * SIN(RADIANS((D21) - INDEX('Dataset_Wisata'!$D$12:$D$622, MATCH('Dashboard'!$C$9, 'Dataset_Wisata'!$A$12:$A$622, 0)))/2)^2)) * 1.3 | J21: =ROUND(I21 * IF('Dashboard'!$C$6<=1, 2250, IF('Dashboard'!$C$6<=4, 5150, 6000)), 0) | K21: 0.99981265 | L21: 0.00017757184 | M21: 9.7773423e-06 | N21: =ABS(E21-$F$6) | O21: =ABS(E21-$F$7) | P21: =ABS(E21-$F$8) | Q21: =IF(K21>=MAX(L21,M21), "Hemat", IF(L21>=M21, "Balanced", "Premium")) | R21: 0.99981265 | S21: 0.00017757135 | T21: 9.777318e-06 | U21: =ABS(E21-$G$6) | V21: =ABS(E21-$G$7) | W21: =ABS(E21-$G$8) | X21: =IF(R21>=MAX(S21,T21), "Hemat", IF(S21>=T21, "Balanced", "Premium"))
A22: 11 | B22: Taman Wisata Selorejo | C22: -7.8773978 | D22: 112.36103 | E22: 13000 | F22: 4.2 | G22: 4555 | H22: Taman Wisata Selorejo | I22: =6371 * 2 * ASIN(SQRT(SIN(RADIANS((C22) - INDEX('Dataset_Wisata'!$C$12:$C$622, MATCH('Dashboard'!$C$9, 'Dataset_Wisata'!$A$12:$A$622, 0)))/2)^2 + COS(RADIANS(INDEX('Dataset_Wisata'!$C$12:$C$622, MATCH('Dashboard'!$C$9, 'Dataset_Wisata'!$A$12:$A$622, 0)))) * COS(RADIANS(C22)) * SIN(RADIANS((D22) - INDEX('Dataset_Wisata'!$D$12:$D$622, MATCH('Dashboard'!$C$9, 'Dataset_Wisata'!$A$12:$A$622, 0)))/2)^2)) * 1.3 | J22: =ROUND(I22 * IF('Dashboard'!$C$6<=1, 2250, IF('Dashboard'!$C$6<=4, 5150, 6000)), 0) | K22: 0.99048497 | L22: 0.0090723034 | M22: 0.00044272729 | N22: =ABS(E22-$F$6) | O22: =ABS(E22-$F$7) | P22: =ABS(E22-$F$8) | Q22: =IF(K22>=MAX(L22,M22), "Hemat", IF(L22>=M22, "Balanced", "Premium")) | R22: 0.99048498 | S22: 0.0090722969 | T22: 0.00044272711 | U22: =ABS(E22-$G$6) | V22: =ABS(E22-$G$7) | W22: =ABS(E22-$G$8) | X22: =IF(R22>=MAX(S22,T22), "Hemat", IF(S22>=T22, "Balanced", "Premium"))
A23: 12 | B23: Air Terjun Coban Kethak | C23: -7.8028103 | D23: 112.35692 | E23: 5000 | F23: 4.1 | G23: 713 | H23: Wisata Umum | I23: =6371 * 2 * ASIN(SQRT(SIN(RADIANS((C23) - INDEX('Dataset_Wisata'!$C$12:$C$622, MATCH('Dashboard'!$C$9, 'Dataset_Wisata'!$A$12:$A$622, 0)))/2)^2 + COS(RADIANS(INDEX('Dataset_Wisata'!$C$12:$C$622, MATCH('Dashboard'!$C$9, 'Dataset_Wisata'!$A$12:$A$622, 0)))) * COS(RADIANS(C23)) * SIN(RADIANS((D23) - INDEX('Dataset_Wisata'!$D$12:$D$622, MATCH('Dashboard'!$C$9, 'Dataset_Wisata'!$A$12:$A$622, 0)))/2)^2)) * 1.3 | J23: =ROUND(I23 * IF('Dashboard'!$C$6<=1, 2250, IF('Dashboard'!$C$6<=4, 5150, 6000)), 0) | K23: 0.98955665 | L23: 0.0097986114 | M23: 0.00064473421 | N23: =ABS(E23-$F$6) | O23: =ABS(E23-$F$7) | P23: =ABS(E23-$F$8) | Q23: =IF(K23>=MAX(L23,M23), "Hemat", IF(L23>=M23, "Balanced", "Premium")) | R23: 0.98955665 | S23: 0.0097986114 | T23: 0.00064473437 | U23: =ABS(E23-$G$6) | V23: =ABS(E23-$G$7) | W23: =ABS(E23-$G$8) | X23: =IF(R23>=MAX(S23,T23), "Hemat", IF(S23>=T23, "Balanced", "Premium"))
... A622: 629 | B622: Gapura Selamat Datang | C622: -8.0061951 | D622: 112.86791 | E622: 15000 | F622: 4.6 | G622: 355 | H622: Wisata Umum | I622: =6371 * 2 * ASIN(SQRT(SIN(RADIANS((C622) - INDEX('Dataset_Wisata'!$C$12:$C$622, MATCH('Dashboard'!$C$9, 'Dataset_Wisata'!$A$12:$A$622, 0)))/2)^2 + COS(RADIANS(INDEX('Dataset_Wisata'!$C$12:$C$622, MATCH('Dashboard'!$C$9, 'Dataset_Wisata'!$A$12:$A$622, 0)))) * COS(RADIANS(C622)) * SIN(RADIANS((D622) - INDEX('Dataset_Wisata'!$D$12:$D$622, MATCH('Dashboard'!$C$9, 'Dataset_Wisata'!$A$12:$A$622, 0)))/2)^2)) * 1.3 | J622: =ROUND(I622 * IF('Dashboard'!$C$6<=1, 2250, IF('Dashboard'!$C$6<=4, 5150, 6000)), 0) | K622: 0.9744283 | L622: 0.024477127 | M622: 0.0010945682 | N622: =ABS(E622-$F$6) | O622: =ABS(E622-$F$7) | P622: =ABS(E622-$F$8) | Q622: =IF(K622>=MAX(L622,M622), "Hemat", IF(L622>=M622, "Balanced", "Premium")) | R622: 0.97442832 | S622: 0.024477113 | T622: 0.0010945679 | U622: =ABS(E622-$G$6) | V622: =ABS(E622-$G$7) | W622: =ABS(E622-$G$8) | X622: =IF(R622>=MAX(S622,T622), "Hemat", IF(S622>=T622, "Balanced", "Premium"))

Sheet Dataset_Hotel
A1: PRE-PROCESSING & CLUSTERING FUZZY C-MEANS - HOTEL
A4: METADATA & PARAMETER ALGORITMA | E4: PUSAT KLASTER (CENTROID FINAL) - PERSAMAAN [2.2]
A5: Banyak Sampel (n) | C5: =COUNTA(B12:B478) | E5: Kelas Klaster | F5: Standard Centroid (Formula) | G5: Budget Centroid (Formula) | H5: Target Anchor (Rp)
A6: Fuzzifier (m) | C6: 2 | E6: MURAH / HEMAT | F6: =IF(SUMSQ(K12:K478)=0, 0, SUMPRODUCT(K12:K478, K12:K478, E12:E478) / SUMSQ(K12:K478)) | G6: =IF(SUMSQ(R12:R478)=0, 0, SUMPRODUCT(R12:R478, R12:R478, E12:E478) / SUMSQ(R12:R478)) | H6: ='Dashboard'!$E$16 * 0.6
A7: Epsilon Toleransi (e) | C7: 1e-05 | E7: SEDANG / BALANCED | F7: =IF(SUMSQ(L12:L478)=0, 0, SUMPRODUCT(L12:L478, L12:L478, E12:E478) / SUMSQ(L12:L478)) | G7: =IF(SUMSQ(S12:S478)=0, 0, SUMPRODUCT(S12:S478, S12:S478, E12:E478) / SUMSQ(S12:S478)) | H7: ='Dashboard'!$E$16 * 1.0
A8: Jumlah Iterasi Std (t) | C8: 93 | E8: MAHAL / PREMIUM | F8: =IF(SUMSQ(M12:M478)=0, 0, SUMPRODUCT(M12:M478, M12:M478, E12:E478) / SUMSQ(M12:M478)) | G8: =IF(SUMSQ(T12:T478)=0, 0, SUMPRODUCT(T12:T478, T12:T478, E12:E478) / SUMSQ(T12:T478)) | H8: ='Dashboard'!$E$16 * 1.4
A9: Jumlah Iterasi Bgt (t) | C9: 145
A10: ID Tempat | B10: Nama Tempat | C10: Latitude | D10: Longitude | E10: Harga (Rp) | F10: Rating | G10: Jumlah Ulasan | H10: Kategori | I10: Jarak Target (km) | J10: Estimasi Ongkir (Rp) | K10: U_Hemat (Std) | L10: U_Balanced (Std) | M10: U_Premium (Std) | N10: Dist_Hemat (Std) | O10: Dist_Balanced (Std) | P10: Dist_Premium (Std) | Q10: Cluster (Std) | R10: U_Hemat (Bgt) | S10: U_Balanced (Bgt) | T10: U_Premium (Bgt) | U10: Dist_Hemat (Bgt) | V10: Dist_Balanced (Bgt) | W10: Dist_Premium (Bgt) | X10: Cluster (Bgt)
A12: 1 | B12: Selorejo Hotel & Resort | C12: -7.8807182 | D12: 112.3619 | E12: 294840 | F12: 0 | G12: 0 | H12: N/A | I12: =6371 * 2 * ASIN(SQRT(SIN(RADIANS((C12) - INDEX('Dataset_Wisata'!$C$12:$C$622, MATCH('Dashboard'!$C$9, 'Dataset_Wisata'!$A$12:$A$622, 0)))/2)^2 + COS(RADIANS(INDEX('Dataset_Wisata'!$C$12:$C$622, MATCH('Dashboard'!$C$9, 'Dataset_Wisata'!$A$12:$A$622, 0)))) * COS(RADIANS(C12)) * SIN(RADIANS((D12) - INDEX('Dataset_Wisata'!$D$12:$D$622, MATCH('Dashboard'!$C$9, 'Dataset_Wisata'!$A$12:$A$622, 0)))/2)^2)) * 1.3 | J12: =ROUND(I12 * IF('Dashboard'!$C$6<=1, 2250, IF('Dashboard'!$C$6<=4, 5150, 6000)), 0) | K12: 0.066502682 | L12: 0.79079384 | M12: 0.14270347 | N12: =ABS(E12-$F$6) | O12: =ABS(E12-$F$7) | P12: =ABS(E12-$F$8) | Q12: =IF(K12>=MAX(L12,M12), "Hemat", IF(L12>=M12, "Balanced", "Premium")) | R12: 0.066501482 | S12: 0.79080214 | T12: 0.14269638 | U12: =ABS(E12-$G$6) | V12: =ABS(E12-$G$7) | W12: =ABS(E12-$G$8) | X12: =IF(R12>=MAX(S12,T12), "Hemat", IF(S12>=T12, "Balanced", "Premium"))
A13: 2 | B13: Grand Pujon View Hotel and Resort | C13: -7.8540616 | D13: 112.49252 | E13: 314885 | F13: 0 | G13: 0 | H13: N/A | I13: =6371 * 2 * ASIN(SQRT(SIN(RADIANS((C13) - INDEX('Dataset_Wisata'!$C$12:$C$622, MATCH('Dashboard'!$C$9, 'Dataset_Wisata'!$A$12:$A$622, 0)))/2)^2 + COS(RADIANS(INDEX('Dataset_Wisata'!$C$12:$C$622, MATCH('Dashboard'!$C$9, 'Dataset_Wisata'!$A$12:$A$622, 0)))) * COS(RADIANS(C13)) * SIN(RADIANS((D13) - INDEX('Dataset_Wisata'!$D$12:$D$622, MATCH('Dashboard'!$C$9, 'Dataset_Wisata'!$A$12:$A$622, 0)))/2)^2)) * 1.3 | J13: =ROUND(I13 * IF('Dashboard'!$C$6<=1, 2250, IF('Dashboard'!$C$6<=4, 5150, 6000)), 0) | K13: 0.080447577 | L13: 0.60501672 | M13: 0.31453571 | N13: =ABS(E13-$F$6) | O13: =ABS(E13-$F$7) | P13: =ABS(E13-$F$8) | Q13: =IF(K13>=MAX(L13,M13), "Hemat", IF(L13>=M13, "Balanced", "Premium")) | R13: 0.080447559 | S13: 0.60502856 | T13: 0.31452388 | U13: =ABS(E13-$G$6) | V13: =ABS(E13-$G$7) | W13: =ABS(E13-$G$8) | X13: =IF(R13>=MAX(S13,T13), "Hemat", IF(S13>=T13, "Balanced", "Premium"))
A14: 3 | B14: Hotel Panorama | C14: -7.862986 | D14: 112.48179 | E14: 393589 | F14: 0 | G14: 0 | H14: N/A | I14: =6371 * 2 * ASIN(SQRT(SIN(RADIANS((C14) - INDEX('Dataset_Wisata'!$C$12:$C$622, MATCH('Dashboard'!$C$9, 'Dataset_Wisata'!$A$12:$A$622, 0)))/2)^2 + COS(RADIANS(INDEX('Dataset_Wisata'!$C$12:$C$622, MATCH('Dashboard'!$C$9, 'Dataset_Wisata'!$A$12:$A$622, 0)))) * COS(RADIANS(C14)) * SIN(RADIANS((D14) - INDEX('Dataset_Wisata'!$D$12:$D$622, MATCH('Dashboard'!$C$9, 'Dataset_Wisata'!$A$12:$A$622, 0)))/2)^2)) * 1.3 | J14: =ROUND(I14 * IF('Dashboard'!$C$6<=1, 2250, IF('Dashboard'!$C$6<=4, 5150, 6000)), 0) | K14: 0.0042441592 | L14: 0.014014959 | M14: 0.98174088 | N14: =ABS(E14-$F$6) | O14: =ABS(E14-$F$7) | P14: =ABS(E14-$F$8) | Q14: =IF(K14>=MAX(L14,M14), "Hemat", IF(L14>=M14, "Balanced", "Premium")) | R14: 0.0042449585 | S14: 0.014017721 | T14: 0.98173732 | U14: =ABS(E14-$G$6) | V14: =ABS(E14-$G$7) | W14: =ABS(E14-$G$8) | X14: =IF(R14>=MAX(S14,T14), "Hemat", IF(S14>=T14, "Balanced", "Premium"))
A15: 4 | B15: PHR GT2.BALEKAMBANG PENGINAPAN PANTAI | C15: -8.4028241 | D15: 112.54089 | E15: 150000 | F15: 0 | G15: 0 | H15: N/A | I15: =6371 * 2 * ASIN(SQRT(SIN(RADIANS((C15) - INDEX('Dataset_Wisata'!$C$12:$C$622, MATCH('Dashboard'!$C$9, 'Dataset_Wisata'!$A$12:$A$622, 0)))/2)^2 + COS(RADIANS(INDEX('Dataset_Wisata'!$C$12:$C$622, MATCH('Dashboard'!$C$9, 'Dataset_Wisata'!$A$12:$A$622, 0)))) * COS(RADIANS(C15)) * SIN(RADIANS((D15) - INDEX('Dataset_Wisata'!$D$12:$D$622, MATCH('Dashboard'!$C$9, 'Dataset_Wisata'!$A$12:$A$622, 0)))/2)^2)) * 1.3 | J15: =ROUND(I15 * IF('Dashboard'!$C$6<=1, 2250, IF('Dashboard'!$C$6<=4, 5150, 6000)), 0) | K15: 0.92365684 | L15: 0.067368992 | M15: 0.00897417 | N15: =ABS(E15-$F$6) | O15: =ABS(E15-$F$7) | P15: =ABS(E15-$F$8) | Q15: =IF(K15>=MAX(L15,M15), "Hemat", IF(L15>=M15, "Balanced", "Premium")) | R15: 0.92365923 | S15: 0.067366852 | T15: 0.0089739149 | U15: =ABS(E15-$G$6) | V15: =ABS(E15-$G$7) | W15: =ABS(E15-$G$8) | X15: =IF(R15>=MAX(S15,T15), "Hemat", IF(S15>=T15, "Balanced", "Premium"))
A16: 5 | B16: OYO 3289 Penginapan Dita Family | C16: -8.1591458 | D16: 112.45928 | E16: 68656 | F16: 0 | G16: 0 | H16: N/A | I16: =6371 * 2 * ASIN(SQRT(SIN(RADIANS((C16) - INDEX('Dataset_Wisata'!$C$12:$C$622, MATCH('Dashboard'!$C$9, 'Dataset_Wisata'!$A$12:$A$622, 0)))/2)^2 + COS(RADIANS(INDEX('Dataset_Wisata'!$C$12:$C$622, MATCH('Dashboard'!$C$9, 'Dataset_Wisata'!$A$12:$A$622, 0)))) * COS(RADIANS(C16)) * SIN(RADIANS((D16) - INDEX('Dataset_Wisata'!$D$12:$D$622, MATCH('Dashboard'!$C$9, 'Dataset_Wisata'!$A$12:$A$622, 0)))/2)^2)) * 1.3 | J16: =ROUND(I16 * IF('Dashboard'!$C$6<=1, 2250, IF('Dashboard'!$C$6<=4, 5150, 6000)), 0) | K16: 0.88867368 | L16: 0.08793678 | M16: 0.023389538 | N16: =ABS(E16-$F$6) | O16: =ABS(E16-$F$7) | P16: =ABS(E16-$F$8) | Q16: =IF(K16>=MAX(L16,M16), "Hemat", IF(L16>=M16, "Balanced", "Premium")) | R16: 0.88867374 | S16: 0.087936754 | T16: 0.023389506 | U16: =ABS(E16-$G$6) | V16: =ABS(E16-$G$7) | W16: =ABS(E16-$G$8) | X16: =IF(R16>=MAX(S16,T16), "Hemat", IF(S16>=T16, "Balanced", "Premium"))
A17: 6 | B17: LG Homestay | C17: -8.1279916 | D17: 112.57488 | E17: 150000 | F17: 0 | G17: 0 | H17: N/A | I17: =6371 * 2 * ASIN(SQRT(SIN(RADIANS((C17) - INDEX('Dataset_Wisata'!$C$12:$C$622, MATCH('Dashboard'!$C$9, 'Dataset_Wisata'!$A$12:$A$622, 0)))/2)^2 + COS(RADIANS(INDEX('Dataset_Wisata'!$C$12:$C$622, MATCH('Dashboard'!$C$9, 'Dataset_Wisata'!$A$12:$A$622, 0)))) * COS(RADIANS(C17)) * SIN(RADIANS((D17) - INDEX('Dataset_Wisata'!$D$12:$D$622, MATCH('Dashboard'!$C$9, 'Dataset_Wisata'!$A$12:$A$622, 0)))/2)^2)) * 1.3 | J17: =ROUND(I17 * IF('Dashboard'!$C$6<=1, 2250, IF('Dashboard'!$C$6<=4, 5150, 6000)), 0) | K17: 0.92365684 | L17: 0.067368992 | M17: 0.00897417 | N17: =ABS(E17-$F$6) | O17: =ABS(E17-$F$7) | P17: =ABS(E17-$F$8) | Q17: =IF(K17>=MAX(L17,M17), "Hemat", IF(L17>=M17, "Balanced", "Premium")) | R17: 0.92365923 | S17: 0.067366852 | T17: 0.0089739149 | U17: =ABS(E17-$G$6) | V17: =ABS(E17-$G$7) | W17: =ABS(E17-$G$8) | X17: =IF(R17>=MAX(S17,T17), "Hemat", IF(S17>=T17, "Balanced", "Premium"))
A18: 7 | B18: Penginapan KaliBiru | C18: -8.1414661 | D18: 112.521 | E18: 75000 | F18: 0 | G18: 0 | H18: N/A | I18: =6371 * 2 * ASIN(SQRT(SIN(RADIANS((C18) - INDEX('Dataset_Wisata'!$C$12:$C$622, MATCH('Dashboard'!$C$9, 'Dataset_Wisata'!$A$12:$A$622, 0)))/2)^2 + COS(RADIANS(INDEX('Dataset_Wisata'!$C$12:$C$622, MATCH('Dashboard'!$C$9, 'Dataset_Wisata'!$A$12:$A$622, 0)))) * COS(RADIANS(C18)) * SIN(RADIANS((D18) - INDEX('Dataset_Wisata'!$D$12:$D$622, MATCH('Dashboard'!$C$9, 'Dataset_Wisata'!$A$12:$A$622, 0)))/2)^2)) * 1.3 | J18: =ROUND(I18 * IF('Dashboard'!$C$6<=1, 2250, IF('Dashboard'!$C$6<=4, 5150, 6000)), 0) | K18: 0.90498708 | L18: 0.075608584 | M18: 0.019404338 | N18: =ABS(E18-$F$6) | O18: =ABS(E18-$F$7) | P18: =ABS(E18-$F$8) | Q18: =IF(K18>=MAX(L18,M18), "Hemat", IF(L18>=M18, "Balanced", "Premium")) | R18: 0.90498706 | S18: 0.075608613 | T18: 0.019404327 | U18: =ABS(E18-$G$6) | V18: =ABS(E18-$G$7) | W18: =ABS(E18-$G$8) | X18: =IF(R18>=MAX(S18,T18), "Hemat", IF(S18>=T18, "Balanced", "Premium"))
A19: 8 | B19: RedDoorz @ Sangnala Homestay Pakisaji | C19: -8.0590716 | D19: 112.60157 | E19: 141969 | F19: 0 | G19: 0 | H19: N/A | I19: =6371 * 2 * ASIN(SQRT(SIN(RADIANS((C19) - INDEX('Dataset_Wisata'!$C$12:$C$622, MATCH('Dashboard'!$C$9, 'Dataset_Wisata'!$A$12:$A$622, 0)))/2)^2 + COS(RADIANS(INDEX('Dataset_Wisata'!$C$12:$C$622, MATCH('Dashboard'!$C$9, 'Dataset_Wisata'!$A$12:$A$622, 0)))) * COS(RADIANS(C19)) * SIN(RADIANS((D19) - INDEX('Dataset_Wisata'!$D$12:$D$622, MATCH('Dashboard'!$C$9, 'Dataset_Wisata'!$A$12:$A$622, 0)))/2)^2)) * 1.3 | J19: =ROUND(I19 * IF('Dashboard'!$C$6<=1, 2250, IF('Dashboard'!$C$6<=4, 5150, 6000)), 0) | K19: 0.96738274 | L19: 0.028427362 | M19: 0.0041899024 | N19: =ABS(E19-$F$6) | O19: =ABS(E19-$F$7) | P19: =ABS(E19-$F$8) | Q19: =IF(K19>=MAX(L19,M19), "Hemat", IF(L19>=M19, "Balanced", "Premium")) | R19: 0.96738403 | S19: 0.028426226 | T19: 0.0041897452 | U19: =ABS(E19-$G$6) | V19: =ABS(E19-$G$7) | W19: =ABS(E19-$G$8) | X19: =IF(R19>=MAX(S19,T19), "Hemat", IF(S19>=T19, "Balanced", "Premium"))
A20: 9 | B20: House of Melati Syariah | C20: -8.1336264 | D20: 112.5676 | E20: 140000 | F20: 0 | G20: 0 | H20: N/A | I20: =6371 * 2 * ASIN(SQRT(SIN(RADIANS((C20) - INDEX('Dataset_Wisata'!$C$12:$C$622, MATCH('Dashboard'!$C$9, 'Dataset_Wisata'!$A$12:$A$622, 0)))/2)^2 + COS(RADIANS(INDEX('Dataset_Wisata'!$C$12:$C$622, MATCH('Dashboard'!$C$9, 'Dataset_Wisata'!$A$12:$A$622, 0)))) * COS(RADIANS(C20)) * SIN(RADIANS((D20) - INDEX('Dataset_Wisata'!$D$12:$D$622, MATCH('Dashboard'!$C$9, 'Dataset_Wisata'!$A$12:$A$622, 0)))/2)^2)) * 1.3 | J20: =ROUND(I20 * IF('Dashboard'!$C$6<=1, 2250, IF('Dashboard'!$C$6<=4, 5150, 6000)), 0) | K20: 0.97491265 | L20: 0.02179911 | M20: 0.0032882431 | N20: =ABS(E20-$F$6) | O20: =ABS(E20-$F$7) | P20: =ABS(E20-$F$8) | Q20: =IF(K20>=MAX(L20,M20), "Hemat", IF(L20>=M20, "Balanced", "Premium")) | R20: 0.97491372 | S20: 0.021798168 | T20: 0.0032881085 | U20: =ABS(E20-$G$6) | V20: =ABS(E20-$G$7) | W20: =ABS(E20-$G$8) | X20: =IF(R20>=MAX(S20,T20), "Hemat", IF(S20>=T20, "Balanced", "Premium"))
A21: 10 | B21: SPOT ON 90797 Sukun Syariah Homestay | C21: -8.0091813 | D21: 112.62038 | E21: 58306 | F21: 0 | G21: 0 | H21: N/A | I21: =6371 * 2 * ASIN(SQRT(SIN(RADIANS((C21) - INDEX('Dataset_Wisata'!$C$12:$C$622, MATCH('Dashboard'!$C$9, 'Dataset_Wisata'!$A$12:$A$622, 0)))/2)^2 + COS(RADIANS(INDEX('Dataset_Wisata'!$C$12:$C$622, MATCH('Dashboard'!$C$9, 'Dataset_Wisata'!$A$12:$A$622, 0)))) * COS(RADIANS(C21)) * SIN(RADIANS((D21) - INDEX('Dataset_Wisata'!$D$12:$D$622, MATCH('Dashboard'!$C$9, 'Dataset_Wisata'!$A$12:$A$622, 0)))/2)^2)) * 1.3 | J21: =ROUND(I21 * IF('Dashboard'!$C$6<=1, 2250, IF('Dashboard'!$C$6<=4, 5150, 6000)), 0) | K21: 0.86270571 | L21: 0.10719176 | M21: 0.03010253 | N21: =ABS(E21-$F$6) | O21: =ABS(E21-$F$7) | P21: =ABS(E21-$F$8) | Q21: =IF(K21>=MAX(L21,M21), "Hemat", IF(L21>=M21, "Balanced", "Premium")) | R21: 0.86270588 | S21: 0.10719166 | T21: 0.030102462 | U21: =ABS(E21-$G$6) | V21: =ABS(E21-$G$7) | W21: =ABS(E21-$G$8) | X21: =IF(R21>=MAX(S21,T21), "Hemat", IF(S21>=T21, "Balanced", "Premium"))
A22: 11 | B22: Bromo Family Guest House | C22: -8.124673 | D22: 112.56563 | E22: 150000 | F22: 0 | G22: 0 | H22: N/A | I22: =6371 * 2 * ASIN(SQRT(SIN(RADIANS((C22) - INDEX('Dataset_Wisata'!$C$12:$C$622, MATCH('Dashboard'!$C$9, 'Dataset_Wisata'!$A$12:$A$622, 0)))/2)^2 + COS(RADIANS(INDEX('Dataset_Wisata'!$C$12:$C$622, MATCH('Dashboard'!$C$9, 'Dataset_Wisata'!$A$12:$A$622, 0)))) * COS(RADIANS(C22)) * SIN(RADIANS((D22) - INDEX('Dataset_Wisata'!$D$12:$D$622, MATCH('Dashboard'!$C$9, 'Dataset_Wisata'!$A$12:$A$622, 0)))/2)^2)) * 1.3 | J22: =ROUND(I22 * IF('Dashboard'!$C$6<=1, 2250, IF('Dashboard'!$C$6<=4, 5150, 6000)), 0) | K22: 0.92365684 | L22: 0.067368992 | M22: 0.00897417 | N22: =ABS(E22-$F$6) | O22: =ABS(E22-$F$7) | P22: =ABS(E22-$F$8) | Q22: =IF(K22>=MAX(L22,M22), "Hemat", IF(L22>=M22, "Balanced", "Premium")) | R22: 0.92365923 | S22: 0.067366852 | T22: 0.0089739149 | U22: =ABS(E22-$G$6) | V22: =ABS(E22-$G$7) | W22: =ABS(E22-$G$8) | X22: =IF(R22>=MAX(S22,T22), "Hemat", IF(S22>=T22, "Balanced", "Premium"))
A23: 12 | B23: Isro Guest House Syariah /Hotel | C23: -8.1327983 | D23: 112.56839 | E23: 149093 | F23: 0 | G23: 0 | H23: N/A | I23: =6371 * 2 * ASIN(SQRT(SIN(RADIANS((C23) - INDEX('Dataset_Wisata'!$C$12:$C$622, MATCH('Dashboard'!$C$9, 'Dataset_Wisata'!$A$12:$A$622, 0)))/2)^2 + COS(RADIANS(INDEX('Dataset_Wisata'!$C$12:$C$622, MATCH('Dashboard'!$C$9, 'Dataset_Wisata'!$A$12:$A$622, 0)))) * COS(RADIANS(C23)) * SIN(RADIANS((D23) - INDEX('Dataset_Wisata'!$D$12:$D$622, MATCH('Dashboard'!$C$9, 'Dataset_Wisata'!$A$12:$A$622, 0)))/2)^2)) * 1.3 | J23: =ROUND(I23 * IF('Dashboard'!$C$6<=1, 2250, IF('Dashboard'!$C$6<=4, 5150, 6000)), 0) | K23: 0.92971471 | L23: 0.061935328 | M23: 0.008349964 | N23: =ABS(E23-$F$6) | O23: =ABS(E23-$F$7) | P23: =ABS(E23-$F$8) | Q23: =IF(K23>=MAX(L23,M23), "Hemat", IF(L23>=M23, "Balanced", "Premium")) | R23: 0.92971696 | S23: 0.061933319 | T23: 0.0083497201 | U23: =ABS(E23-$G$6) | V23: =ABS(E23-$G$7) | W23: =ABS(E23-$G$8) | X23: =IF(R23>=MAX(S23,T23), "Hemat", IF(S23>=T23, "Balanced", "Premium"))
... A478: 467 | B478: Homestay Maria | C478: -7.9837794 | D478: 112.90632 | E478: 148129 | F478: 0 | G478: 0 | H478: N/A | I478: =6371 * 2 * ASIN(SQRT(SIN(RADIANS((C478) - INDEX('Dataset_Wisata'!$C$12:$C$622, MATCH('Dashboard'!$C$9, 'Dataset_Wisata'!$A$12:$A$622, 0)))/2)^2 + COS(RADIANS(INDEX('Dataset_Wisata'!$C$12:$C$622, MATCH('Dashboard'!$C$9, 'Dataset_Wisata'!$A$12:$A$622, 0)))) * COS(RADIANS(C478)) * SIN(RADIANS((D478) - INDEX('Dataset_Wisata'!$D$12:$D$622, MATCH('Dashboard'!$C$9, 'Dataset_Wisata'!$A$12:$A$622, 0)))/2)^2)) * 1.3 | J478: =ROUND(I478 * IF('Dashboard'!$C$6<=1, 2250, IF('Dashboard'!$C$6<=4, 5150, 6000)), 0) | K478: 0.93582841 | L478: 0.056462976 | M478: 0.007708614 | N478: =ABS(E478-$F$6) | O478: =ABS(E478-$F$7) | P478: =ABS(E478-$F$8) | Q478: =IF(K478>=MAX(L478,M478), "Hemat", IF(L478>=M478, "Balanced", "Premium")) | R478: 0.93583052 | S478: 0.056461101 | T478: 0.007708382 | U478: =ABS(E478-$G$6) | V478: =ABS(E478-$G$7) | W478: =ABS(E478-$G$8) | X478: =IF(R478>=MAX(S478,T478), "Hemat", IF(S478>=T478, "Balanced", "Premium"))

Sheet Dataset_Kuliner
A1: PRE-PROCESSING & CLUSTERING FUZZY C-MEANS - KULINER
A4: METADATA & PARAMETER ALGORITMA | E4: PUSAT KLASTER (CENTROID FINAL) - PERSAMAAN [2.2]
A5: Banyak Sampel (n) | C5: =COUNTA(B12:B651) | E5: Kelas Klaster | F5: Standard Centroid (Formula) | G5: Budget Centroid (Formula) | H5: Target Anchor (Rp)
A6: Fuzzifier (m) | C6: 2 | E6: MURAH / HEMAT | F6: =IF(SUMSQ(K12:K651)=0, 0, SUMPRODUCT(K12:K651, K12:K651, E12:E651) / SUMSQ(K12:K651)) | G6: =IF(SUMSQ(R12:R651)=0, 0, SUMPRODUCT(R12:R651, R12:R651, E12:E651) / SUMSQ(R12:R651)) | H6: ='Dashboard'!$E$18 * 0.6
A7: Epsilon Toleransi (e) | C7: 1e-05 | E7: SEDANG / BALANCED | F7: =IF(SUMSQ(L12:L651)=0, 0, SUMPRODUCT(L12:L651, L12:L651, E12:E651) / SUMSQ(L12:L651)) | G7: =IF(SUMSQ(S12:S651)=0, 0, SUMPRODUCT(S12:S651, S12:S651, E12:E651) / SUMSQ(S12:S651)) | H7: ='Dashboard'!$E$18 * 1.0
A8: Jumlah Iterasi Std (t) | C8: 69 | E8: MAHAL / PREMIUM | F8: =IF(SUMSQ(M12:M651)=0, 0, SUMPRODUCT(M12:M651, M12:M651, E12:E651) / SUMSQ(M12:M651)) | G8: =IF(SUMSQ(T12:T651)=0, 0, SUMPRODUCT(T12:T651, T12:T651, E12:E651) / SUMSQ(T12:T651)) | H8: ='Dashboard'!$E$18 * 1.4
A9: Jumlah Iterasi Bgt (t) | C9: 60
A10: ID Tempat | B10: Nama Tempat | C10: Latitude | D10: Longitude | E10: Harga (Rp) | F10: Rating | G10: Jumlah Ulasan | H10: Kategori | I10: Jarak Target (km) | J10: Estimasi Ongkir (Rp) | K10: U_Hemat (Std) | L10: U_Balanced (Std) | M10: U_Premium (Std) | N10: Dist_Hemat (Std) | O10: Dist_Balanced (Std) | P10: Dist_Premium (Std) | Q10: Cluster (Std) | R10: U_Hemat (Bgt) | S10: U_Balanced (Bgt) | T10: U_Premium (Bgt) | U10: Dist_Hemat (Bgt) | V10: Dist_Balanced (Bgt) | W10: Dist_Premium (Bgt) | X10: Cluster (Bgt)
A12: 1 | B12: Depot 2 Legenda | C12: -7.9399474 | D12: 112.63566 | E12: 35385 | F12: 4.5 | G12: 917 | H12: Wisata Umum | I12: =6371 * 2 * ASIN(SQRT(SIN(RADIANS((C12) - INDEX('Dataset_Wisata'!$C$12:$C$622, MATCH('Dashboard'!$C$9, 'Dataset_Wisata'!$A$12:$A$622, 0)))/2)^2 + COS(RADIANS(INDEX('Dataset_Wisata'!$C$12:$C$622, MATCH('Dashboard'!$C$9, 'Dataset_Wisata'!$A$12:$A$622, 0)))) * COS(RADIANS(C12)) * SIN(RADIANS((D12) - INDEX('Dataset_Wisata'!$D$12:$D$622, MATCH('Dashboard'!$C$9, 'Dataset_Wisata'!$A$12:$A$622, 0)))/2)^2)) * 1.3 | J12: =ROUND(I12 * IF('Dashboard'!$C$6<=1, 2250, IF('Dashboard'!$C$6<=4, 5150, 6000)), 0) | K12: 0.11794988 | L12: 0.57713887 | M12: 0.30491125 | N12: =ABS(E12-$F$6) | O12: =ABS(E12-$F$7) | P12: =ABS(E12-$F$8) | Q12: =IF(K12>=MAX(L12,M12), "Hemat", IF(L12>=M12, "Balanced", "Premium")) | R12: 0.11794989 | S12: 0.57713863 | T12: 0.30491148 | U12: =ABS(E12-$G$6) | V12: =ABS(E12-$G$7) | W12: =ABS(E12-$G$8) | X12: =IF(R12>=MAX(S12,T12), "Hemat", IF(S12>=T12, "Balanced", "Premium"))
A13: 2 | B13: Depot Semangkok | C13: -7.9385565 | D13: 112.63728 | E13: 25000 | F13: 4.3 | G13: 478 | H13: Wisata Umum | I13: =6371 * 2 * ASIN(SQRT(SIN(RADIANS((C13) - INDEX('Dataset_Wisata'!$C$12:$C$622, MATCH('Dashboard'!$C$9, 'Dataset_Wisata'!$A$12:$A$622, 0)))/2)^2 + COS(RADIANS(INDEX('Dataset_Wisata'!$C$12:$C$622, MATCH('Dashboard'!$C$9, 'Dataset_Wisata'!$A$12:$A$622, 0)))) * COS(RADIANS(C13)) * SIN(RADIANS((D13) - INDEX('Dataset_Wisata'!$D$12:$D$622, MATCH('Dashboard'!$C$9, 'Dataset_Wisata'!$A$12:$A$622, 0)))/2)^2)) * 1.3 | J13: =ROUND(I13 * IF('Dashboard'!$C$6<=1, 2250, IF('Dashboard'!$C$6<=4, 5150, 6000)), 0) | K13: 0.00094605096 | L13: 0.99882911 | M13: 0.00022483613 | N13: =ABS(E13-$F$6) | O13: =ABS(E13-$F$7) | P13: =ABS(E13-$F$8) | Q13: =IF(K13>=MAX(L13,M13), "Hemat", IF(L13>=M13, "Balanced", "Premium")) | R13: 0.00094603686 | S13: 0.99882913 | T13: 0.00022483288 | U13: =ABS(E13-$G$6) | V13: =ABS(E13-$G$7) | W13: =ABS(E13-$G$8) | X13: =IF(R13>=MAX(S13,T13), "Hemat", IF(S13>=T13, "Balanced", "Premium"))
A14: 3 | B14: Rumah Makan Hok Lay | C14: -7.9845499 | D14: 112.63428 | E14: 43750 | F14: 4.4 | G14: 4519 | H14: Wisata Umum | I14: =6371 * 2 * ASIN(SQRT(SIN(RADIANS((C14) - INDEX('Dataset_Wisata'!$C$12:$C$622, MATCH('Dashboard'!$C$9, 'Dataset_Wisata'!$A$12:$A$622, 0)))/2)^2 + COS(RADIANS(INDEX('Dataset_Wisata'!$C$12:$C$622, MATCH('Dashboard'!$C$9, 'Dataset_Wisata'!$A$12:$A$622, 0)))) * COS(RADIANS(C14)) * SIN(RADIANS((D14) - INDEX('Dataset_Wisata'!$D$12:$D$622, MATCH('Dashboard'!$C$9, 'Dataset_Wisata'!$A$12:$A$622, 0)))/2)^2)) * 1.3 | J14: =ROUND(I14 * IF('Dashboard'!$C$6<=1, 2250, IF('Dashboard'!$C$6<=4, 5150, 6000)), 0) | K14: 0.028205764 | L14: 0.0777836 | M14: 0.89401064 | N14: =ABS(E14-$F$6) | O14: =ABS(E14-$F$7) | P14: =ABS(E14-$F$8) | Q14: =IF(K14>=MAX(L14,M14), "Hemat", IF(L14>=M14, "Balanced", "Premium")) | R14: 0.028205723 | S14: 0.077783466 | T14: 0.89401081 | U14: =ABS(E14-$G$6) | V14: =ABS(E14-$G$7) | W14: =ABS(E14-$G$8) | X14: =IF(R14>=MAX(S14,T14), "Hemat", IF(S14>=T14, "Balanced", "Premium"))
A15: 4 | B15: Depot Gang Djangkrik | C15: -7.9568232 | D15: 112.63846 | E15: 65714 | F15: 4.5 | G15: 4159 | H15: Wisata Umum | I15: =6371 * 2 * ASIN(SQRT(SIN(RADIANS((C15) - INDEX('Dataset_Wisata'!$C$12:$C$622, MATCH('Dashboard'!$C$9, 'Dataset_Wisata'!$A$12:$A$622, 0)))/2)^2 + COS(RADIANS(INDEX('Dataset_Wisata'!$C$12:$C$622, MATCH('Dashboard'!$C$9, 'Dataset_Wisata'!$A$12:$A$622, 0)))) * COS(RADIANS(C15)) * SIN(RADIANS((D15) - INDEX('Dataset_Wisata'!$D$12:$D$622, MATCH('Dashboard'!$C$9, 'Dataset_Wisata'!$A$12:$A$622, 0)))/2)^2)) * 1.3 | J15: =ROUND(I15 * IF('Dashboard'!$C$6<=1, 2250, IF('Dashboard'!$C$6<=4, 5150, 6000)), 0) | K15: 0.078328028 | L15: 0.13258629 | M15: 0.78908569 | N15: =ABS(E15-$F$6) | O15: =ABS(E15-$F$7) | P15: =ABS(E15-$F$8) | Q15: =IF(K15>=MAX(L15,M15), "Hemat", IF(L15>=M15, "Balanced", "Premium")) | R15: 0.07832806 | S15: 0.13258633 | T15: 0.78908561 | U15: =ABS(E15-$G$6) | V15: =ABS(E15-$G$7) | W15: =ABS(E15-$G$8) | X15: =IF(R15>=MAX(S15,T15), "Hemat", IF(S15>=T15, "Balanced", "Premium"))
A16: 5 | B16: Melati Restaurant | C16: -7.9770541 | D16: 112.63287 | E16: 36000 | F16: 4.7 | G16: 1255 | H16: Wisata Umum | I16: =6371 * 2 * ASIN(SQRT(SIN(RADIANS((C16) - INDEX('Dataset_Wisata'!$C$12:$C$622, MATCH('Dashboard'!$C$9, 'Dataset_Wisata'!$A$12:$A$622, 0)))/2)^2 + COS(RADIANS(INDEX('Dataset_Wisata'!$C$12:$C$622, MATCH('Dashboard'!$C$9, 'Dataset_Wisata'!$A$12:$A$622, 0)))) * COS(RADIANS(C16)) * SIN(RADIANS((D16) - INDEX('Dataset_Wisata'!$D$12:$D$622, MATCH('Dashboard'!$C$9, 'Dataset_Wisata'!$A$12:$A$622, 0)))/2)^2)) * 1.3 | J16: =ROUND(I16 * IF('Dashboard'!$C$6<=1, 2250, IF('Dashboard'!$C$6<=4, 5150, 6000)), 0) | K16: 0.11655851 | L16: 0.53476857 | M16: 0.34867292 | N16: =ABS(E16-$F$6) | O16: =ABS(E16-$F$7) | P16: =ABS(E16-$F$8) | Q16: =IF(K16>=MAX(L16,M16), "Hemat", IF(L16>=M16, "Balanced", "Premium")) | R16: 0.11655851 | S16: 0.53476832 | T16: 0.34867317 | U16: =ABS(E16-$G$6) | V16: =ABS(E16-$G$7) | W16: =ABS(E16-$G$8) | X16: =IF(R16>=MAX(S16,T16), "Hemat", IF(S16>=T16, "Balanced", "Premium"))
A17: 6 | B17: Depot Santai | C17: -7.9667822 | D17: 112.62899 | E17: 50000 | F17: 4.4 | G17: 610 | H17: Wisata Umum | I17: =6371 * 2 * ASIN(SQRT(SIN(RADIANS((C17) - INDEX('Dataset_Wisata'!$C$12:$C$622, MATCH('Dashboard'!$C$9, 'Dataset_Wisata'!$A$12:$A$622, 0)))/2)^2 + COS(RADIANS(INDEX('Dataset_Wisata'!$C$12:$C$622, MATCH('Dashboard'!$C$9, 'Dataset_Wisata'!$A$12:$A$622, 0)))) * COS(RADIANS(C17)) * SIN(RADIANS((D17) - INDEX('Dataset_Wisata'!$D$12:$D$622, MATCH('Dashboard'!$C$9, 'Dataset_Wisata'!$A$12:$A$622, 0)))/2)^2)) * 1.3 | J17: =ROUND(I17 * IF('Dashboard'!$C$6<=1, 2250, IF('Dashboard'!$C$6<=4, 5150, 6000)), 0) | K17: 0.00050384339 | L17: 0.0011231631 | M17: 0.99837299 | N17: =ABS(E17-$F$6) | O17: =ABS(E17-$F$7) | P17: =ABS(E17-$F$8) | Q17: =IF(K17>=MAX(L17,M17), "Hemat", IF(L17>=M17, "Balanced", "Premium")) | R17: 0.00050384873 | S17: 0.0011231748 | T17: 0.99837298 | U17: =ABS(E17-$G$6) | V17: =ABS(E17-$G$7) | W17: =ABS(E17-$G$8) | X17: =IF(R17>=MAX(S17,T17), "Hemat", IF(S17>=T17, "Balanced", "Premium"))
A18: 7 | B18: Depot Asem Djawa | C18: -7.9373203 | D18: 112.57959 | E18: 25000 | F18: 4.8 | G18: 57 | H18: Wisata Umum | I18: =6371 * 2 * ASIN(SQRT(SIN(RADIANS((C18) - INDEX('Dataset_Wisata'!$C$12:$C$622, MATCH('Dashboard'!$C$9, 'Dataset_Wisata'!$A$12:$A$622, 0)))/2)^2 + COS(RADIANS(INDEX('Dataset_Wisata'!$C$12:$C$622, MATCH('Dashboard'!$C$9, 'Dataset_Wisata'!$A$12:$A$622, 0)))) * COS(RADIANS(C18)) * SIN(RADIANS((D18) - INDEX('Dataset_Wisata'!$D$12:$D$622, MATCH('Dashboard'!$C$9, 'Dataset_Wisata'!$A$12:$A$622, 0)))/2)^2)) * 1.3 | J18: =ROUND(I18 * IF('Dashboard'!$C$6<=1, 2250, IF('Dashboard'!$C$6<=4, 5150, 6000)), 0) | K18: 0.00094605096 | L18: 0.99882911 | M18: 0.00022483613 | N18: =ABS(E18-$F$6) | O18: =ABS(E18-$F$7) | P18: =ABS(E18-$F$8) | Q18: =IF(K18>=MAX(L18,M18), "Hemat", IF(L18>=M18, "Balanced", "Premium")) | R18: 0.00094603686 | S18: 0.99882913 | T18: 0.00022483288 | U18: =ABS(E18-$G$6) | V18: =ABS(E18-$G$7) | W18: =ABS(E18-$G$8) | X18: =IF(R18>=MAX(S18,T18), "Hemat", IF(S18>=T18, "Balanced", "Premium"))
A19: 8 | B19: Depot Dua Satu | C19: -7.9675082 | D19: 112.629 | E19: 46000 | F19: 4.5 | G19: 703 | H19: Wisata Umum | I19: =6371 * 2 * ASIN(SQRT(SIN(RADIANS((C19) - INDEX('Dataset_Wisata'!$C$12:$C$622, MATCH('Dashboard'!$C$9, 'Dataset_Wisata'!$A$12:$A$622, 0)))/2)^2 + COS(RADIANS(INDEX('Dataset_Wisata'!$C$12:$C$622, MATCH('Dashboard'!$C$9, 'Dataset_Wisata'!$A$12:$A$622, 0)))) * COS(RADIANS(C19)) * SIN(RADIANS((D19) - INDEX('Dataset_Wisata'!$D$12:$D$622, MATCH('Dashboard'!$C$9, 'Dataset_Wisata'!$A$12:$A$622, 0)))/2)^2)) * 1.3 | J19: =ROUND(I19 * IF('Dashboard'!$C$6<=1, 2250, IF('Dashboard'!$C$6<=4, 5150, 6000)), 0) | K19: 0.0090712118 | L19: 0.022892903 | M19: 0.96803589 | N19: =ABS(E19-$F$6) | O19: =ABS(E19-$F$7) | P19: =ABS(E19-$F$8) | Q19: =IF(K19>=MAX(L19,M19), "Hemat", IF(L19>=M19, "Balanced", "Premium")) | R19: 0.0090711872 | S19: 0.022892836 | T19: 0.96803598 | U19: =ABS(E19-$G$6) | V19: =ABS(E19-$G$7) | W19: =ABS(E19-$G$8) | X19: =IF(R19>=MAX(S19,T19), "Hemat", IF(S19>=T19, "Balanced", "Premium"))
A20: 9 | B20: Warung Wareg | C20: -7.9111853 | D20: 112.62218 | E20: 40084 | F20: 4.4 | G20: 6404 | H20: Warung Wareg | I20: =6371 * 2 * ASIN(SQRT(SIN(RADIANS((C20) - INDEX('Dataset_Wisata'!$C$12:$C$622, MATCH('Dashboard'!$C$9, 'Dataset_Wisata'!$A$12:$A$622, 0)))/2)^2 + COS(RADIANS(INDEX('Dataset_Wisata'!$C$12:$C$622, MATCH('Dashboard'!$C$9, 'Dataset_Wisata'!$A$12:$A$622, 0)))) * COS(RADIANS(C20)) * SIN(RADIANS((D20) - INDEX('Dataset_Wisata'!$D$12:$D$622, MATCH('Dashboard'!$C$9, 'Dataset_Wisata'!$A$12:$A$622, 0)))/2)^2)) * 1.3 | J20: =ROUND(I20 * IF('Dashboard'!$C$6<=1, 2250, IF('Dashboard'!$C$6<=4, 5150, 6000)), 0) | K20: 0.076517345 | L20: 0.25489388 | M20: 0.66858878 | N20: =ABS(E20-$F$6) | O20: =ABS(E20-$F$7) | P20: =ABS(E20-$F$8) | Q20: =IF(K20>=MAX(L20,M20), "Hemat", IF(L20>=M20, "Balanced", "Premium")) | R20: 0.076517299 | S20: 0.25489364 | T20: 0.66858906 | U20: =ABS(E20-$G$6) | V20: =ABS(E20-$G$7) | W20: =ABS(E20-$G$8) | X20: =IF(R20>=MAX(S20,T20), "Hemat", IF(S20>=T20, "Balanced", "Premium"))
A21: 10 | B21: Rawon Nguling | C21: -7.983913 | D21: 112.63398 | E21: 34400 | F21: 4.5 | G21: 8062 | H21: Wisata Umum | I21: =6371 * 2 * ASIN(SQRT(SIN(RADIANS((C21) - INDEX('Dataset_Wisata'!$C$12:$C$622, MATCH('Dashboard'!$C$9, 'Dataset_Wisata'!$A$12:$A$622, 0)))/2)^2 + COS(RADIANS(INDEX('Dataset_Wisata'!$C$12:$C$622, MATCH('Dashboard'!$C$9, 'Dataset_Wisata'!$A$12:$A$622, 0)))) * COS(RADIANS(C21)) * SIN(RADIANS((D21) - INDEX('Dataset_Wisata'!$D$12:$D$622, MATCH('Dashboard'!$C$9, 'Dataset_Wisata'!$A$12:$A$622, 0)))/2)^2)) * 1.3 | J21: =ROUND(I21 * IF('Dashboard'!$C$6<=1, 2250, IF('Dashboard'!$C$6<=4, 5150, 6000)), 0) | K21: 0.11694289 | L21: 0.64259725 | M21: 0.24045986 | N21: =ABS(E21-$F$6) | O21: =ABS(E21-$F$7) | P21: =ABS(E21-$F$8) | Q21: =IF(K21>=MAX(L21,M21), "Hemat", IF(L21>=M21, "Balanced", "Premium")) | R21: 0.11694291 | S21: 0.64259703 | T21: 0.24046006 | U21: =ABS(E21-$G$6) | V21: =ABS(E21-$G$7) | W21: =ABS(E21-$G$8) | X21: =IF(R21>=MAX(S21,T21), "Hemat", IF(S21>=T21, "Balanced", "Premium"))
A22: 11 | B22: Warung Bu Kus | C22: -7.7953348 | D22: 112.3492 | E22: 15000 | F22: 4.4 | G22: 52 | H22: Warung Bu Kus | I22: =6371 * 2 * ASIN(SQRT(SIN(RADIANS((C22) - INDEX('Dataset_Wisata'!$C$12:$C$622, MATCH('Dashboard'!$C$9, 'Dataset_Wisata'!$A$12:$A$622, 0)))/2)^2 + COS(RADIANS(INDEX('Dataset_Wisata'!$C$12:$C$622, MATCH('Dashboard'!$C$9, 'Dataset_Wisata'!$A$12:$A$622, 0)))) * COS(RADIANS(C22)) * SIN(RADIANS((D22) - INDEX('Dataset_Wisata'!$D$12:$D$622, MATCH('Dashboard'!$C$9, 'Dataset_Wisata'!$A$12:$A$622, 0)))/2)^2)) * 1.3 | J22: =ROUND(I22 * IF('Dashboard'!$C$6<=1, 2250, IF('Dashboard'!$C$6<=4, 5150, 6000)), 0) | K22: 0.96862832 | L22: 0.028729905 | M22: 0.0026417776 | N22: =ABS(E22-$F$6) | O22: =ABS(E22-$F$7) | P22: =ABS(E22-$F$8) | Q22: =IF(K22>=MAX(L22,M22), "Hemat", IF(L22>=M22, "Balanced", "Premium")) | R22: 0.96862828 | S22: 0.02872994 | T22: 0.0026417801 | U22: =ABS(E22-$G$6) | V22: =ABS(E22-$G$7) | W22: =ABS(E22-$G$8) | X22: =IF(R22>=MAX(S22,T22), "Hemat", IF(S22>=T22, "Balanced", "Premium"))
A23: 12 | B23: Warung Bu Kati | C23: -7.7952242 | D23: 112.31332 | E23: 17000 | F23: 4.5 | G23: 30 | H23: Warung Bu Kati | I23: =6371 * 2 * ASIN(SQRT(SIN(RADIANS((C23) - INDEX('Dataset_Wisata'!$C$12:$C$622, MATCH('Dashboard'!$C$9, 'Dataset_Wisata'!$A$12:$A$622, 0)))/2)^2 + COS(RADIANS(INDEX('Dataset_Wisata'!$C$12:$C$622, MATCH('Dashboard'!$C$9, 'Dataset_Wisata'!$A$12:$A$622, 0)))) * COS(RADIANS(C23)) * SIN(RADIANS((D23) - INDEX('Dataset_Wisata'!$D$12:$D$622, MATCH('Dashboard'!$C$9, 'Dataset_Wisata'!$A$12:$A$622, 0)))/2)^2)) * 1.3 | J23: =ROUND(I23 * IF('Dashboard'!$C$6<=1, 2250, IF('Dashboard'!$C$6<=4, 5150, 6000)), 0) | K23: 0.8205767 | L23: 0.16806856 | M23: 0.011354748 | N23: =ABS(E23-$F$6) | O23: =ABS(E23-$F$7) | P23: =ABS(E23-$F$8) | Q23: =IF(K23>=MAX(L23,M23), "Hemat", IF(L23>=M23, "Balanced", "Premium")) | R23: 0.82057656 | S23: 0.16806869 | T23: 0.011354753 | U23: =ABS(E23-$G$6) | V23: =ABS(E23-$G$7) | W23: =ABS(E23-$G$8) | X23: =IF(R23>=MAX(S23,T23), "Hemat", IF(S23>=T23, "Balanced", "Premium"))
... A651: 640 | B651: Chill coffee | C651: -8.0150703 | D651: 112.84904 | E651: 20000 | F651: 4.3 | G651: 220 | H651: Restoran · Jl. Raya Gubugklakah | I651: =6371 * 2 * ASIN(SQRT(SIN(RADIANS((C651) - INDEX('Dataset_Wisata'!$C$12:$C$622, MATCH('Dashboard'!$C$9, 'Dataset_Wisata'!$A$12:$A$622, 0)))/2)^2 + COS(RADIANS(INDEX('Dataset_Wisata'!$C$12:$C$622, MATCH('Dashboard'!$C$9, 'Dataset_Wisata'!$A$12:$A$622, 0)))) * COS(RADIANS(C651)) * SIN(RADIANS((D651) - INDEX('Dataset_Wisata'!$D$12:$D$622, MATCH('Dashboard'!$C$9, 'Dataset_Wisata'!$A$12:$A$622, 0)))/2)^2)) * 1.3 | J651: =ROUND(I651 * IF('Dashboard'!$C$6<=1, 2250, IF('Dashboard'!$C$6<=4, 5150, 6000)), 0) | K651: 0.37668645 | L651: 0.60294043 | M651: 0.020373126 | N651: =ABS(E651-$F$6) | O651: =ABS(E651-$F$7) | P651: =ABS(E651-$F$8) | Q651: =IF(K651>=MAX(L651,M651), "Hemat", IF(L651>=M651, "Balanced", "Premium")) | R651: 0.37668617 | S651: 0.60294071 | T651: 0.020373122 | U651: =ABS(E651-$G$6) | V651: =ABS(E651-$G$7) | W651: =ABS(E651-$G$8) | X651: =IF(R651>=MAX(S651,T651), "Hemat", IF(S651>=T651, "Balanced", "Premium"))

Sheet Evaluasi_FCM_XieBeni
A1: EVALUASI METODE KLASTERING & INDEKS VALIDITAS XIE-BENI
A4: ANALISIS VALIDITAS KLASTER SECARA FORMULA AKTIF (PERSAMAAN 2.6 - 2.8)
A5: Parameter Evaluasi | B5: Wisata (Standard) | C5: Wisata (Budget) | D5: Hotel (Standard) | E5: Hotel (Budget) | F5: Kuliner (Standard) | G5: Kuliner (Budget)
A6: Banyak Sampel Data (n) | B6: ='Dataset_Wisata'!C5 | C6: ='Dataset_Wisata'!C5 | D6: ='Dataset_Hotel'!C5 | E6: ='Dataset_Hotel'!C5 | F6: ='Dataset_Kuliner'!C5 | G6: ='Dataset_Kuliner'!C5
A7: Pangkat Fuzzifier (m) | B7: 2 | C7: 2 | D7: 2 | E7: 2 | F7: 2 | G7: 2
A8: Total Variansi Intra-Klaster (σ) [Eq. 2.6] | B8: =SUMPRODUCT('Dataset_Wisata'!K12:K622, 'Dataset_Wisata'!K12:K622, 'Dataset_Wisata'!N12:N622, 'Dataset_Wisata'!N12:N622) + SUMPRODUCT('Dataset_Wisata'!L12:L622, 'Dataset_Wisata'!L12:L622, 'Dataset_Wisata'!O12:O622, 'Dataset_Wisata'!O12:O622) + SUMPRODUCT('Dataset_Wisata'!M12:M622, 'Dataset_Wisata'!M12:M622, 'Dataset_Wisata'!P12:P622, 'Dataset_Wisata'!P12:P622) | C8: =SUMPRODUCT('Dataset_Wisata'!R12:R622, 'Dataset_Wisata'!R12:R622, 'Dataset_Wisata'!U12:U622, 'Dataset_Wisata'!U12:U622) + SUMPRODUCT('Dataset_Wisata'!S12:S622, 'Dataset_Wisata'!S12:S622, 'Dataset_Wisata'!V12:V622, 'Dataset_Wisata'!V12:V622) + SUMPRODUCT('Dataset_Wisata'!T12:T622, 'Dataset_Wisata'!T12:T622, 'Dataset_Wisata'!W12:W622, 'Dataset_Wisata'!W12:W622) | D8: =SUMPRODUCT('Dataset_Hotel'!K12:K478, 'Dataset_Hotel'!K12:K478, 'Dataset_Hotel'!N12:N478, 'Dataset_Hotel'!N12:N478) + SUMPRODUCT('Dataset_Hotel'!L12:L478, 'Dataset_Hotel'!L12:L478, 'Dataset_Hotel'!O12:O478, 'Dataset_Hotel'!O12:O478) + SUMPRODUCT('Dataset_Hotel'!M12:M478, 'Dataset_Hotel'!M12:M478, 'Dataset_Hotel'!P12:P478, 'Dataset_Hotel'!P12:P478) | E8: =SUMPRODUCT('Dataset_Hotel'!R12:R478, 'Dataset_Hotel'!R12:R478, 'Dataset_Hotel'!U12:U478, 'Dataset_Hotel'!U12:U478) + SUMPRODUCT('Dataset_Hotel'!S12:S478, 'Dataset_Hotel'!S12:S478, 'Dataset_Hotel'!V12:V478, 'Dataset_Hotel'!V12:V478) + SUMPRODUCT('Dataset_Hotel'!T12:T478, 'Dataset_Hotel'!T12:T478, 'Dataset_Hotel'!W12:W478, 'Dataset_Hotel'!W12:W478) | F8: =SUMPRODUCT('Dataset_Kuliner'!K12:K651, 'Dataset_Kuliner'!K12:K651, 'Dataset_Kuliner'!N12:N651, 'Dataset_Kuliner'!N12:N651) + SUMPRODUCT('Dataset_Kuliner'!L12:L651, 'Dataset_Kuliner'!L12:L651, 'Dataset_Kuliner'!O12:O651, 'Dataset_Kuliner'!O12:O651) + SUMPRODUCT('Dataset_Kuliner'!M12:M651, 'Dataset_Kuliner'!M12:M651, 'Dataset_Kuliner'!P12:P651, 'Dataset_Kuliner'!P12:P651) | G8: =SUMPRODUCT('Dataset_Kuliner'!R12:R651, 'Dataset_Kuliner'!R12:R651, 'Dataset_Kuliner'!U12:U651, 'Dataset_Kuliner'!U12:U651) + SUMPRODUCT('Dataset_Kuliner'!S12:S651, 'Dataset_Kuliner'!S12:S651, 'Dataset_Kuliner'!V12:V651, 'Dataset_Kuliner'!V12:V651) + SUMPRODUCT('Dataset_Kuliner'!T12:T651, 'Dataset_Kuliner'!T12:T651, 'Dataset_Kuliner'!W12:W651, 'Dataset_Kuliner'!W12:W651)
A9: Separasi Centroid Minimum (sep) [Eq. 2.7] | B9: =MIN(('Dataset_Wisata'!F6-'Dataset_Wisata'!F7)^2, ('Dataset_Wisata'!F7-'Dataset_Wisata'!F8)^2, ('Dataset_Wisata'!F6-'Dataset_Wisata'!F8)^2) | C9: =MIN(('Dataset_Wisata'!G6-'Dataset_Wisata'!G7)^2, ('Dataset_Wisata'!G7-'Dataset_Wisata'!G8)^2, ('Dataset_Wisata'!G6-'Dataset_Wisata'!G8)^2) | D9: =MIN(('Dataset_Hotel'!F6-'Dataset_Hotel'!F7)^2, ('Dataset_Hotel'!F7-'Dataset_Hotel'!F8)^2, ('Dataset_Hotel'!F6-'Dataset_Hotel'!F8)^2) | E9: =MIN(('Dataset_Hotel'!G6-'Dataset_Hotel'!G7)^2, ('Dataset_Hotel'!G7-'Dataset_Hotel'!G8)^2, ('Dataset_Hotel'!G6-'Dataset_Hotel'!G8)^2) | F9: =MIN(('Dataset_Kuliner'!F6-'Dataset_Kuliner'!F7)^2, ('Dataset_Kuliner'!F7-'Dataset_Kuliner'!F8)^2, ('Dataset_Kuliner'!F6-'Dataset_Kuliner'!F8)^2) | G9: =MIN(('Dataset_Kuliner'!G6-'Dataset_Kuliner'!G7)^2, ('Dataset_Kuliner'!G7-'Dataset_Kuliner'!G8)^2, ('Dataset_Kuliner'!G6-'Dataset_Kuliner'!G8)^2)
A10: Indeks Xie-Beni (XB) [Eq. 2.8] | B10: =IFERROR(B8 / (B6 * B9), 0) | C10: =IFERROR(C8 / (C6 * C9), 0) | D10: =IFERROR(D8 / (D6 * D9), 0) | E10: =IFERROR(E8 / (E6 * E9), 0) | F10: =IFERROR(F8 / (F6 * F9), 0) | G10: =IFERROR(G8 / (G6 * G9), 0)

Sheet Workflow_1_BudgetFirst
A1: WORKFLOW SIMULASI REKOMENDASI - BUDGETFIRST
A4: RUJUKAN KENDALA ANGGARAN & KAPASITAS (FORMULA DARI DASHBOARD)
A5: Total Budget Wisatawan | B5: ='Dashboard'!C5
A6: Jumlah Orang (Peserta) | B6: ='Dashboard'!C6
A7: Durasi Liburan (Hari) | B7: ='Dashboard'!C7
A8: Kamar Hotel yang Butuh | B8: =ROUNDUP('Dashboard'!C6/2, 0)
A9: Malam Menginap | B9: =MAX('Dashboard'!C7-1, 1)
A11: Kelas Paket | B11: No | C11: Nama Hotel | D11: Harga Hotel/Malam | E11: Biaya Hotel Total | F11: Nama Wisata Pilihan | G11: Harga Tiket Satuan | H11: Biaya Wisata Total | I11: Nama Kuliner Pilihan | J11: Harga Kuliner/Porsi | K11: Biaya Kuliner Total | L11: Rute Geospasial (km) | M11: Estimasi Ongkir (Rp) | N11: ESTIMASI TOTAL BIAYA (Rp) | O11: SISA BUDGET (Rp) | P11: STATUS KELAYAKAN
A12: HEMAT | B12: Opsi 1 | C12: SR Guesthouse | D12: 173966 | E12: =D12 * B$9 * B$8 | F12: Kusuma Edukasi Pertanian | G12: 25000 | H12: =G12 * B$6 | I12: Warung Bu Mariani | J12: 15000 | K12: =J12 * B$6 * 3 * B$7 | L12: =(6371 * 2 * ASIN(SQRT(SIN(RADIANS((-7.8805418)-(-7.8630288))/2)^2 + COS(RADIANS(-7.8630288)) * COS(RADIANS(-7.8805418)) * SIN(RADIANS((112.5140954)-(112.5116416))/2)^2)) * 1.3) + (6371 * 2 * ASIN(SQRT(SIN(RADIANS((-7.859017)-(-7.8805418))/2)^2 + COS(RADIANS(-7.8805418)) * COS(RADIANS(-7.859017)) * SIN(RADIANS((112.509584)-(112.5140954))/2)^2)) * 1.3) + (6371 * 2 * ASIN(SQRT(SIN(RADIANS((-7.8630288)-(-7.859017))/2)^2 + COS(RADIANS(-7.859017)) * COS(RADIANS(-7.8630288)) * SIN(RADIANS((112.5116416)-(112.509584))/2)^2)) * 1.3) | M12: =ROUND(L12 * IF(B$6<=1, 2250, IF(B$6<=4, 5150, 6000)), 0) | N12: =E12 + H12 + K12 + M12 | O12: =B$5 - N12 | P12: =IF(N12<=B$5, "✅ LAYAK (UNDER BUDGET)", "⚠️ TIDAK LAYAK (OVER BUDGET)")
A13: HEMAT | B13: Opsi 2 | C13: RedDoorz Plus near Balai Kota Batu 2 | D13: 180000 | E13: =D13 * B$9 * B$8 | F13: Kusuma Edukasi Pertanian | G13: 25000 | H13: =G13 * B$6 | I13: Warung Bu Mariani | J13: 15000 | K13: =J13 * B$6 * 3 * B$7 | L13: =(6371 * 2 * ASIN(SQRT(SIN(RADIANS((-7.8805418)-(-7.8650022))/2)^2 + COS(RADIANS(-7.8650022)) * COS(RADIANS(-7.8805418)) * SIN(RADIANS((112.5140954)-(112.506961))/2)^2)) * 1.3) + (6371 * 2 * ASIN(SQRT(SIN(RADIANS((-7.859017)-(-7.8805418))/2)^2 + COS(RADIANS(-7.8805418)) * COS(RADIANS(-7.859017)) * SIN(RADIANS((112.509584)-(112.5140954))/2)^2)) * 1.3) + (6371 * 2 * ASIN(SQRT(SIN(RADIANS((-7.8650022)-(-7.859017))/2)^2 + COS(RADIANS(-7.859017)) * COS(RADIANS(-7.8650022)) * SIN(RADIANS((112.506961)-(112.509584))/2)^2)) * 1.3) | M13: =ROUND(L13 * IF(B$6<=1, 2250, IF(B$6<=4, 5150, 6000)), 0) | N13: =E13 + H13 + K13 + M13 | O13: =B$5 - N13 | P13: =IF(N13<=B$5, "✅ LAYAK (UNDER BUDGET)", "⚠️ TIDAK LAYAK (OVER BUDGET)")
A14: HEMAT | B14: Opsi 3 | C14: SR Guesthouse | D14: 173966 | E14: =D14 * B$9 * B$8 | F14: Kusuma Waterpark | G14: 25000 | H14: =G14 * B$6 | I14: Warung Bu Mariani | J14: 15000 | K14: =J14 * B$6 * 3 * B$7 | L14: =(6371 * 2 * ASIN(SQRT(SIN(RADIANS((-7.8816345)-(-7.8630288))/2)^2 + COS(RADIANS(-7.8630288)) * COS(RADIANS(-7.8816345)) * SIN(RADIANS((112.5148178)-(112.5116416))/2)^2)) * 1.3) + (6371 * 2 * ASIN(SQRT(SIN(RADIANS((-7.859017)-(-7.8816345))/2)^2 + COS(RADIANS(-7.8816345)) * COS(RADIANS(-7.859017)) * SIN(RADIANS((112.509584)-(112.5148178))/2)^2)) * 1.3) + (6371 * 2 * ASIN(SQRT(SIN(RADIANS((-7.8630288)-(-7.859017))/2)^2 + COS(RADIANS(-7.859017)) * COS(RADIANS(-7.8630288)) * SIN(RADIANS((112.5116416)-(112.509584))/2)^2)) * 1.3) | M14: =ROUND(L14 * IF(B$6<=1, 2250, IF(B$6<=4, 5150, 6000)), 0) | N14: =E14 + H14 + K14 + M14 | O14: =B$5 - N14 | P14: =IF(N14<=B$5, "✅ LAYAK (UNDER BUDGET)", "⚠️ TIDAK LAYAK (OVER BUDGET)")
A15: HEMAT | B15: Opsi 4 | C15: RedDoorz Plus near Balai Kota Batu 2 | D15: 180000 | E15: =D15 * B$9 * B$8 | F15: Kusuma Waterpark | G15: 25000 | H15: =G15 * B$6 | I15: Warung Bu Mariani | J15: 15000 | K15: =J15 * B$6 * 3 * B$7 | L15: =(6371 * 2 * ASIN(SQRT(SIN(RADIANS((-7.8816345)-(-7.8650022))/2)^2 + COS(RADIANS(-7.8650022)) * COS(RADIANS(-7.8816345)) * SIN(RADIANS((112.5148178)-(112.506961))/2)^2)) * 1.3) + (6371 * 2 * ASIN(SQRT(SIN(RADIANS((-7.859017)-(-7.8816345))/2)^2 + COS(RADIANS(-7.8816345)) * COS(RADIANS(-7.859017)) * SIN(RADIANS((112.509584)-(112.5148178))/2)^2)) * 1.3) + (6371 * 2 * ASIN(SQRT(SIN(RADIANS((-7.8650022)-(-7.859017))/2)^2 + COS(RADIANS(-7.859017)) * COS(RADIANS(-7.8650022)) * SIN(RADIANS((112.506961)-(112.509584))/2)^2)) * 1.3) | M15: =ROUND(L15 * IF(B$6<=1, 2250, IF(B$6<=4, 5150, 6000)), 0) | N15: =E15 + H15 + K15 + M15 | O15: =B$5 - N15 | P15: =IF(N15<=B$5, "✅ LAYAK (UNDER BUDGET)", "⚠️ TIDAK LAYAK (OVER BUDGET)")
A16: HEMAT | B16: Opsi 5 | C16: SR Guesthouse | D16: 173966 | E16: =D16 * B$9 * B$8 | F16: wisata petik jeruk super agro kota batu | G16: 25000 | H16: =G16 * B$6 | I16: Warung Bu Mariani | J16: 15000 | K16: =J16 * B$6 * 3 * B$7 | L16: =(6371 * 2 * ASIN(SQRT(SIN(RADIANS((-7.8333467)-(-7.8630288))/2)^2 + COS(RADIANS(-7.8630288)) * COS(RADIANS(-7.8333467)) * SIN(RADIANS((112.5216271)-(112.5116416))/2)^2)) * 1.3) + (6371 * 2 * ASIN(SQRT(SIN(RADIANS((-7.859017)-(-7.8333467))/2)^2 + COS(RADIANS(-7.8333467)) * COS(RADIANS(-7.859017)) * SIN(RADIANS((112.509584)-(112.5216271))/2)^2)) * 1.3) + (6371 * 2 * ASIN(SQRT(SIN(RADIANS((-7.8630288)-(-7.859017))/2)^2 + COS(RADIANS(-7.859017)) * COS(RADIANS(-7.8630288)) * SIN(RADIANS((112.5116416)-(112.509584))/2)^2)) * 1.3) | M16: =ROUND(L16 * IF(B$6<=1, 2250, IF(B$6<=4, 5150, 6000)), 0) | N16: =E16 + H16 + K16 + M16 | O16: =B$5 - N16 | P16: =IF(N16<=B$5, "✅ LAYAK (UNDER BUDGET)", "⚠️ TIDAK LAYAK (OVER BUDGET)")
A17: BALANCED | B17: Opsi 1 | C17: D'Fresh Guest House and Resto | D17: 327600 | E17: =D17 * B$9 * B$8 | F17: Hawai Waterpark | G17: 85000 | H17: =G17 * B$6 | I17: Depot Mentari | J17: 25000 | K17: =J17 * B$6 * 3 * B$7 | L17: =(6371 * 2 * ASIN(SQRT(SIN(RADIANS((-7.9234101)-(-7.9396721))/2)^2 + COS(RADIANS(-7.9396721)) * COS(RADIANS(-7.9234101)) * SIN(RADIANS((112.657862)-(112.633534))/2)^2)) * 1.3) + (6371 * 2 * ASIN(SQRT(SIN(RADIANS((-7.9387725)-(-7.9234101))/2)^2 + COS(RADIANS(-7.9234101)) * COS(RADIANS(-7.9387725)) * SIN(RADIANS((112.6333279)-(112.657862))/2)^2)) * 1.3) + (6371 * 2 * ASIN(SQRT(SIN(RADIANS((-7.9396721)-(-7.9387725))/2)^2 + COS(RADIANS(-7.9387725)) * COS(RADIANS(-7.9396721)) * SIN(RADIANS((112.633534)-(112.6333279))/2)^2)) * 1.3) | M17: =ROUND(L17 * IF(B$6<=1, 2250, IF(B$6<=4, 5150, 6000)), 0) | N17: =E17 + H17 + K17 + M17 | O17: =B$5 - N17 | P17: =IF(N17<=B$5, "✅ LAYAK (UNDER BUDGET)", "⚠️ TIDAK LAYAK (OVER BUDGET)")
A18: BALANCED | B18: Opsi 2 | C18: D'Fresh Guest House and Resto | D18: 327600 | E18: =D18 * B$9 * B$8 | F18: Hawai Waterpark | G18: 85000 | H18: =G18 * B$6 | I18: Depot Semangkok | J18: 25000 | K18: =J18 * B$6 * 3 * B$7 | L18: =(6371 * 2 * ASIN(SQRT(SIN(RADIANS((-7.9234101)-(-7.9396721))/2)^2 + COS(RADIANS(-7.9396721)) * COS(RADIANS(-7.9234101)) * SIN(RADIANS((112.657862)-(112.633534))/2)^2)) * 1.3) + (6371 * 2 * ASIN(SQRT(SIN(RADIANS((-7.9385565)-(-7.9234101))/2)^2 + COS(RADIANS(-7.9234101)) * COS(RADIANS(-7.9385565)) * SIN(RADIANS((112.6372841)-(112.657862))/2)^2)) * 1.3) + (6371 * 2 * ASIN(SQRT(SIN(RADIANS((-7.9396721)-(-7.9385565))/2)^2 + COS(RADIANS(-7.9385565)) * COS(RADIANS(-7.9396721)) * SIN(RADIANS((112.633534)-(112.6372841))/2)^2)) * 1.3) | M18: =ROUND(L18 * IF(B$6<=1, 2250, IF(B$6<=4, 5150, 6000)), 0) | N18: =E18 + H18 + K18 + M18 | O18: =B$5 - N18 | P18: =IF(N18<=B$5, "✅ LAYAK (UNDER BUDGET)", "⚠️ TIDAK LAYAK (OVER BUDGET)")
A19: BALANCED | B19: Opsi 3 | C19: Hotel Grage Malang | D19: 315315 | E19: =D19 * B$9 * B$8 | F19: Hawai Waterpark | G19: 85000 | H19: =G19 * B$6 | I19: Depot Mentari | J19: 25000 | K19: =J19 * B$6 * 3 * B$7 | L19: =(6371 * 2 * ASIN(SQRT(SIN(RADIANS((-7.9234101)-(-7.9119162))/2)^2 + COS(RADIANS(-7.9119162)) * COS(RADIANS(-7.9234101)) * SIN(RADIANS((112.657862)-(112.6404563))/2)^2)) * 1.3) + (6371 * 2 * ASIN(SQRT(SIN(RADIANS((-7.9387725)-(-7.9234101))/2)^2 + COS(RADIANS(-7.9234101)) * COS(RADIANS(-7.9387725)) * SIN(RADIANS((112.6333279)-(112.657862))/2)^2)) * 1.3) + (6371 * 2 * ASIN(SQRT(SIN(RADIANS((-7.9119162)-(-7.9387725))/2)^2 + COS(RADIANS(-7.9387725)) * COS(RADIANS(-7.9119162)) * SIN(RADIANS((112.6404563)-(112.6333279))/2)^2)) * 1.3) | M19: =ROUND(L19 * IF(B$6<=1, 2250, IF(B$6<=4, 5150, 6000)), 0) | N19: =E19 + H19 + K19 + M19 | O19: =B$5 - N19 | P19: =IF(N19<=B$5, "✅ LAYAK (UNDER BUDGET)", "⚠️ TIDAK LAYAK (OVER BUDGET)")
